Workbook

Sheet 33kV (Main)
F2: CBA SWITCHGEAR TEST SHEET (PMU/PPU/SSU)
V3: Page No:
V4: CBM Condition
B5: 1.0 Job Details: | J5: 2.0 Switchgear Details: | R5: 3.0 Background Data
B6: 1.1 Substation Name: | J6: 2.1 Manufacture: | R6: 3.1 Background Temp (ɛ = 1.0):
B7: 1.2 Substation Location: | J7: 2.2 Manufacturing Year: | R7: 3.2 Humidity:
B8: 1.3 Date of Scanning: | J8: 2.3 Model: | R8: 3.3 Background (TEV):
B9: 1.4 Time: | J9: 2.4 Last Preventive Maintenance Date:
J10: 2.4 Type of Busbar:
J11: 2.5 Rating (kV):
B13: NO. | C13: PANEL NO. | D13: FEEDER NAME | E13: CABLE TYPE | F13: BREAKER POSITION | G13: BREAKER STATUS | H13: BUSBAR POSITION | I13: LOAD (A) | J13: HEATER (A) WHEN ON / OFF | K13: COMPARTMENT | L13: THERMOGRAPHY | R13: TEV | T13: ULTRASOUND
L14: REF. TEMP (°C) | M14: MAX TEMP (°C) | N14: ∆T | O14: AVG TEMP (°C) | P14: Image No. | Q14: Remarks / Other Defects | R14: Reading (dB) | S14: Pulses / Cycle | T14: Reading (dB) | U14: Type of Characteristic | V14: Remarks / Other Defects
B15: 1 | J15: ON | K15: BREAKER | N15: =IF(M15="","",M15-L15) | O15: =IF(M15="","",((L15+M15)/2)) | S15: =IF(R15<>"", 0, "")
K16: CABLE | N16: =IF(M16="","",M16-L16) | O16: =IF(M16="","",((L16+M16)/2)) | S16: =IF(R16<>"", 0, "")
J17: OFF | K17: BUSBAR (TOP) | N17: =IF(M17="","",M17-L17) | O17: =IF(M17="","",((L17+M17)/2))
J18: =IF(J16="","","0.0") | K18: PT COMPARTMENT | N18: =IF(M18="","",M18-L18) | O18: =IF(M18="","",((L18+M18)/2)) | S18: =IF(R18<>"", 0, "")
K19: CABLE ENTRY | N19: =IF(M19="","",M19-L19) | O19: =IF(M19="","",((L19+M19)/2))
K20: LINK BOX | N20: =IF(M20="","",M20-L20) | O20: =IF(M20="","",((L20+M20)/2))
B21: 2 | J21: ON | K21: BREAKER | N21: =IF(M21="","",M21-L21) | O21: =IF(M21="","",((L21+M21)/2)) | S21: =IF(R21<>"", 0, "")
K22: CABLE | N22: =IF(M22="","",M22-L22) | O22: =IF(M22="","",((L22+M22)/2)) | S22: =IF(R22<>"", 0, "")
J23: OFF | K23: BUSBAR (TOP) | N23: =IF(M23="","",M23-L23) | O23: =IF(M23="","",((L23+M23)/2))
J24: =IF(J22="","","0.0") | K24: PT COMPARTMENT | N24: =IF(M24="","",M24-L24) | O24: =IF(M24="","",((L24+M24)/2)) | S24: =IF(R24<>"", 0, "")
K25: CABLE ENTRY | N25: =IF(M25="","",M25-L25) | O25: =IF(M25="","",((L25+M25)/2))
K26: LINK BOX | N26: =IF(M26="","",M26-L26) | O26: =IF(M26="","",((L26+M26)/2))
B27: 3 | J27: ON | K27: BREAKER | N27: =IF(M27="","",M27-L27) | O27: =IF(M27="","",((L27+M27)/2)) | S27: =IF(R27<>"", 0, "")
K28: CABLE | N28: =IF(M28="","",M28-L28) | O28: =IF(M28="","",((L28+M28)/2)) | S28: =IF(R28<>"", 0, "")
J29: OFF | K29: BUSBAR (TOP) | N29: =IF(M29="","",M29-L29) | O29: =IF(M29="","",((L29+M29)/2))
J30: =IF(J28="","","0.0") | K30: PT COMPARTMENT | N30: =IF(M30="","",M30-L30) | O30: =IF(M30="","",((L30+M30)/2)) | S30: =IF(R30<>"", 0, "")
K31: CABLE ENTRY | N31: =IF(M31="","",M31-L31) | O31: =IF(M31="","",((L31+M31)/2))
K32: LINK BOX | N32: =IF(M32="","",M32-L32) | O32: =IF(M32="","",((L32+M32)/2))
B33: 4 | J33: ON | K33: BREAKER | N33: =IF(M33="","",M33-L33) | O33: =IF(M33="","",((L33+M33)/2)) | S33: =IF(R33<>"", 0, "")
K34: CABLE | N34: =IF(M34="","",M34-L34) | O34: =IF(M34="","",((L34+M34)/2)) | S34: =IF(R34<>"", 0, "")
J35: OFF | K35: BUSBAR (TOP) | N35: =IF(M35="","",M35-L35) | O35: =IF(M35="","",((L35+M35)/2))
J36: =IF(J34="","","0.0") | K36: PT COMPARTMENT | N36: =IF(M36="","",M36-L36) | O36: =IF(M36="","",((L36+M36)/2)) | S36: =IF(R36<>"", 0, "")
K37: CABLE ENTRY | N37: =IF(M37="","",M37-L37) | O37: =IF(M37="","",((L37+M37)/2))
K38: LINK BOX | N38: =IF(M38="","",M38-L38) | O38: =IF(M38="","",((L38+M38)/2))
B39: 5 | J39: ON | K39: BREAKER | N39: =IF(M39="","",M39-L39) | O39: =IF(M39="","",((L39+M39)/2)) | S39: =IF(R39<>"", 0, "")
K40: CABLE | N40: =IF(M40="","",M40-L40) | O40: =IF(M40="","",((L40+M40)/2)) | S40: =IF(R40<>"", 0, "")
J41: OFF | K41: BUSBAR (TOP) | N41: =IF(M41="","",M41-L41) | O41: =IF(M41="","",((L41+M41)/2))
J42: =IF(J40="","","0.0") | K42: PT COMPARTMENT | N42: =IF(M42="","",M42-L42) | O42: =IF(M42="","",((L42+M42)/2)) | S42: =IF(R42<>"", 0, "")
...

Sheet 33kV (Extra)
F2: CBA SWITCHGEAR TEST SHEET (PMU/PPU/SSU) - Page Extra | V2: ='33kV (Main)'!V2
V3: Page No:
V4: CBM Condition
B5: 1.0 Job Details: | J5: 2.0 Switchgear Details: | R5: 3.0 Background Data
B6: 1.1 Substation Name: | D6: ='33kV (Main)'!D6 | J6: 2.1 Manufacture: | L6: ='33kV (Main)'!L6 | M6: ='33kV (Main)'!M6 | R6: 3.1 Background Temp (ɛ = 1.0): | U6: ='33kV (Main)'!U6
B7: 1.2 Substation Location: | D7: ='33kV (Main)'!D7 | J7: 2.2 Manufacturing Year: | L7: ='33kV (Main)'!L7 | R7: 3.2 Humidity: | U7: ='33kV (Main)'!U7
B8: 1.3 Date of Scanning: | D8: ='33kV (Main)'!D8 | J8: 2.3 Model: | L8: ='33kV (Main)'!L8 | R8: 3.3 Background (TEV): | U8: ='33kV (Main)'!U8
B9: 1.4 Time: | D9: ='33kV (Main)'!D9 | J9: 2.4 Last Preventive Maintenance Date: | L9: ='33kV (Main)'!L9
J10: 2.4 Type of Busbar: | L10: ='33kV (Main)'!L10
J11: 2.5 Rating (kV): | L11: ='33kV (Main)'!L11
B13: NO. | C13: PANEL NO. | D13: FEEDER NAME | E13: CABLE TYPE | F13: BREAKER POSITION | G13: BREAKER STATUS | H13: BUSBAR POSITION | I13: LOAD (A) | J13: HEATER (A) WHEN ON / OFF | K13: COMPARTMENT | L13: THERMOGRAPHY | R13: TEV | T13: ULTRASOUND
L14: REF. TEMP (°C) | M14: MAX TEMP (°C) | N14: ∆T | O14: AVG TEMP (°C) | P14: Image No. | Q14: Remarks / Other Defects | R14: Reading (dB) | S14: Pulses / Cycle | T14: Reading (dB) | U14: Type of Characteristic | V14: Remarks / Other Defects
B15: 9 | J15: ON | K15: BREAKER | N15: =IF(M15="","",M15-L15) | O15: =IF(M15="","",((L15+M15)/2)) | S15: =IF(R15<>"", 0, "")
K16: CABLE | N16: =IF(M16="","",M16-L16) | O16: =IF(M16="","",((L16+M16)/2)) | S16: =IF(R16<>"", 0, "")
J17: OFF | K17: BUSBAR (TOP) | N17: =IF(M17="","",M17-L17) | O17: =IF(M17="","",((L17+M17)/2))
J18: =IF(J16="","","0.0") | K18: PT COMPARTMENT | N18: =IF(M18="","",M18-L18) | O18: =IF(M18="","",((L18+M18)/2)) | S18: =IF(R18<>"", 0, "")
K19: CABLE ENTRY | N19: =IF(M19="","",M19-L19) | O19: =IF(M19="","",((L19+M19)/2))
K20: LINK BOX | N20: =IF(M20="","",M20-L20) | O20: =IF(M20="","",((L20+M20)/2))
B21: 10 | J21: ON | K21: BREAKER | N21: =IF(M21="","",M21-L21) | O21: =IF(M21="","",((L21+M21)/2)) | S21: =IF(R21<>"", 0, "")
K22: CABLE | N22: =IF(M22="","",M22-L22) | O22: =IF(M22="","",((L22+M22)/2)) | S22: =IF(R22<>"", 0, "")
J23: OFF | K23: BUSBAR (TOP) | N23: =IF(M23="","",M23-L23) | O23: =IF(M23="","",((L23+M23)/2))
J24: =IF(J22="","","0.0") | K24: PT COMPARTMENT | N24: =IF(M24="","",M24-L24) | O24: =IF(M24="","",((L24+M24)/2)) | S24: =IF(R24<>"", 0, "")
K25: CABLE ENTRY | N25: =IF(M25="","",M25-L25) | O25: =IF(M25="","",((L25+M25)/2))
K26: LINK BOX | N26: =IF(M26="","",M26-L26) | O26: =IF(M26="","",((L26+M26)/2))
B27: 11 | J27: ON | K27: BREAKER | N27: =IF(M27="","",M27-L27) | O27: =IF(M27="","",((L27+M27)/2)) | S27: =IF(R27<>"", 0, "")
K28: CABLE | N28: =IF(M28="","",M28-L28) | O28: =IF(M28="","",((L28+M28)/2)) | S28: =IF(R28<>"", 0, "")
J29: OFF | K29: BUSBAR (TOP) | N29: =IF(M29="","",M29-L29) | O29: =IF(M29="","",((L29+M29)/2))
J30: =IF(J28="","","0.0") | K30: PT COMPARTMENT | N30: =IF(M30="","",M30-L30) | O30: =IF(M30="","",((L30+M30)/2)) | S30: =IF(R30<>"", 0, "")
K31: CABLE ENTRY | N31: =IF(M31="","",M31-L31) | O31: =IF(M31="","",((L31+M31)/2))
K32: LINK BOX | N32: =IF(M32="","",M32-L32) | O32: =IF(M32="","",((L32+M32)/2))
B33: 12 | J33: ON | K33: BREAKER | N33: =IF(M33="","",M33-L33) | O33: =IF(M33="","",((L33+M33)/2)) | S33: =IF(R33<>"", 0, "")
K34: CABLE | N34: =IF(M34="","",M34-L34) | O34: =IF(M34="","",((L34+M34)/2)) | S34: =IF(R34<>"", 0, "")
J35: OFF | K35: BUSBAR (TOP) | N35: =IF(M35="","",M35-L35) | O35: =IF(M35="","",((L35+M35)/2))
J36: =IF(J34="","","0.0") | K36: PT COMPARTMENT | N36: =IF(M36="","",M36-L36) | O36: =IF(M36="","",((L36+M36)/2)) | S36: =IF(R36<>"", 0, "")
K37: CABLE ENTRY | N37: =IF(M37="","",M37-L37) | O37: =IF(M37="","",((L37+M37)/2))
K38: LINK BOX | N38: =IF(M38="","",M38-L38) | O38: =IF(M38="","",((L38+M38)/2))
B39: 13 | J39: ON | K39: BREAKER | N39: =IF(M39="","",M39-L39) | O39: =IF(M39="","",((L39+M39)/2)) | S39: =IF(R39<>"", 0, "")
K40: CABLE | N40: =IF(M40="","",M40-L40) | O40: =IF(M40="","",((L40+M40)/2)) | S40: =IF(R40<>"", 0, "")
J41: OFF | K41: BUSBAR (TOP) | N41: =IF(M41="","",M41-L41) | O41: =IF(M41="","",((L41+M41)/2))
J42: =IF(J40="","","0.0") | K42: PT COMPARTMENT | N42: =IF(M42="","",M42-L42) | O42: =IF(M42="","",((L42+M42)/2)) | S42: =IF(R42<>"", 0, "")
...

Sheet 33kV (Extra) (2)
F2: CBA SWITCHGEAR TEST SHEET (PMU/PPU/SSU) - Page Extra | V2: ='33kV (Main)'!V2
V3: Page No:
V4: CBM Condition
B5: 1.0 Job Details: | J5: 2.0 Switchgear Details: | R5: 3.0 Background Data
B6: 1.1 Substation Name: | D6: ='33kV (Main)'!D6 | J6: 2.1 Manufacture: | L6: ='33kV (Main)'!L6 | M6: ='33kV (Main)'!M6 | R6: 3.1 Background Temp (ɛ = 1.0): | U6: ='33kV (Main)'!U6
B7: 1.2 Substation Location: | D7: ='33kV (Main)'!D7 | J7: 2.2 Manufacturing Year: | L7: ='33kV (Main)'!L7 | R7: 3.2 Humidity: | U7: ='33kV (Main)'!U7
B8: 1.3 Date of Scanning: | D8: ='33kV (Main)'!D8 | J8: 2.3 Model: | L8: ='33kV (Main)'!L8 | R8: 3.3 Background (TEV): | U8: ='33kV (Main)'!U8
B9: 1.4 Time: | D9: ='33kV (Main)'!D9 | J9: 2.4 Last Preventive Maintenance Date: | L9: ='33kV (Main)'!L9
J10: 2.4 Type of Busbar: | L10: ='33kV (Main)'!L10
J11: 2.5 Rating (kV): | L11: ='33kV (Main)'!L11
B13: NO. | C13: PANEL NO. | D13: FEEDER NAME | E13: CABLE TYPE | F13: BREAKER POSITION | G13: BREAKER STATUS | H13: BUSBAR POSITION | I13: LOAD (A) | J13: HEATER (A) WHEN ON / OFF | K13: COMPARTMENT | L13: THERMOGRAPHY | R13: TEV | T13: ULTRASOUND
L14: REF. TEMP (°C) | M14: MAX TEMP (°C) | N14: ∆T | O14: AVG TEMP (°C) | P14: Image No. | Q14: Remarks / Other Defects | R14: Reading (dB) | S14: Pulses / Cycle | T14: Reading (dB) | U14: Type of Characteristic | V14: Remarks / Other Defects
B15: 17 | J15: ON | K15: BREAKER | N15: =IF(M15="","",M15-L15) | O15: =IF(M15="","",((L15+M15)/2)) | S15: =IF(R15<>"", 0, "")
K16: CABLE | N16: =IF(M16="","",M16-L16) | O16: =IF(M16="","",((L16+M16)/2)) | S16: =IF(R16<>"", 0, "")
J17: OFF | K17: BUSBAR (TOP) | N17: =IF(M17="","",M17-L17) | O17: =IF(M17="","",((L17+M17)/2))
J18: =IF(J16="","","0.0") | K18: PT COMPARTMENT | N18: =IF(M18="","",M18-L18) | O18: =IF(M18="","",((L18+M18)/2)) | S18: =IF(R18<>"", 0, "")
K19: CABLE ENTRY | N19: =IF(M19="","",M19-L19) | O19: =IF(M19="","",((L19+M19)/2))
K20: LINK BOX | N20: =IF(M20="","",M20-L20) | O20: =IF(M20="","",((L20+M20)/2))
B21: 18 | J21: ON | K21: BREAKER | N21: =IF(M21="","",M21-L21) | O21: =IF(M21="","",((L21+M21)/2)) | S21: =IF(R21<>"", 0, "")
K22: CABLE | N22: =IF(M22="","",M22-L22) | O22: =IF(M22="","",((L22+M22)/2)) | S22: =IF(R22<>"", 0, "")
J23: OFF | K23: BUSBAR (TOP) | N23: =IF(M23="","",M23-L23) | O23: =IF(M23="","",((L23+M23)/2))
J24: =IF(J22="","","0.0") | K24: PT COMPARTMENT | N24: =IF(M24="","",M24-L24) | O24: =IF(M24="","",((L24+M24)/2)) | S24: =IF(R24<>"", 0, "")
K25: CABLE ENTRY | N25: =IF(M25="","",M25-L25) | O25: =IF(M25="","",((L25+M25)/2))
K26: LINK BOX | N26: =IF(M26="","",M26-L26) | O26: =IF(M26="","",((L26+M26)/2))
B27: 19 | J27: ON | K27: BREAKER | N27: =IF(M27="","",M27-L27) | O27: =IF(M27="","",((L27+M27)/2)) | S27: =IF(R27<>"", 0, "")
K28: CABLE | N28: =IF(M28="","",M28-L28) | O28: =IF(M28="","",((L28+M28)/2)) | S28: =IF(R28<>"", 0, "")
J29: OFF | K29: BUSBAR (TOP) | N29: =IF(M29="","",M29-L29) | O29: =IF(M29="","",((L29+M29)/2))
J30: =IF(J28="","","0.0") | K30: PT COMPARTMENT | N30: =IF(M30="","",M30-L30) | O30: =IF(M30="","",((L30+M30)/2)) | S30: =IF(R30<>"", 0, "")
K31: CABLE ENTRY | N31: =IF(M31="","",M31-L31) | O31: =IF(M31="","",((L31+M31)/2))
K32: LINK BOX | N32: =IF(M32="","",M32-L32) | O32: =IF(M32="","",((L32+M32)/2))
B33: 20 | J33: ON | K33: BREAKER | N33: =IF(M33="","",M33-L33) | O33: =IF(M33="","",((L33+M33)/2)) | S33: =IF(R33<>"", 0, "")
K34: CABLE | N34: =IF(M34="","",M34-L34) | O34: =IF(M34="","",((L34+M34)/2)) | S34: =IF(R34<>"", 0, "")
J35: OFF | K35: BUSBAR (TOP) | N35: =IF(M35="","",M35-L35) | O35: =IF(M35="","",((L35+M35)/2))
J36: =IF(J34="","","0.0") | K36: PT COMPARTMENT | N36: =IF(M36="","",M36-L36) | O36: =IF(M36="","",((L36+M36)/2)) | S36: =IF(R36<>"", 0, "")
K37: CABLE ENTRY | N37: =IF(M37="","",M37-L37) | O37: =IF(M37="","",((L37+M37)/2))
K38: LINK BOX | N38: =IF(M38="","",M38-L38) | O38: =IF(M38="","",((L38+M38)/2))
B39: 21 | J39: ON | K39: BREAKER | N39: =IF(M39="","",M39-L39) | O39: =IF(M39="","",((L39+M39)/2)) | S39: =IF(R39<>"", 0, "")
K40: CABLE | N40: =IF(M40="","",M40-L40) | O40: =IF(M40="","",((L40+M40)/2)) | S40: =IF(R40<>"", 0, "")
J41: OFF | K41: BUSBAR (TOP) | N41: =IF(M41="","",M41-L41) | O41: =IF(M41="","",((L41+M41)/2))
J42: =IF(J40="","","0.0") | K42: PT COMPARTMENT | N42: =IF(M42="","",M42-L42) | O42: =IF(M42="","",((L42+M42)/2)) | S42: =IF(R42<>"", 0, "")
...

Sheet 11kV (Main)
F2: CBA SWITCHGEAR TEST SHEET (PMU/PPU/SSU)
V3: Page No:
V4: CBM Condition
B5: 1.0 Job Details: | J5: 2.0 Switchgear Details: | R5: 3.0 Background Data
B6: 1.1 Substation Name: | D6: ='33kV (Main)'!D6 | J6: 2.1 Manufacture: | R6: 3.1 Background Temp (ɛ = 1.0):
B7: 1.2 Substation Location: | D7: ='33kV (Main)'!D7 | J7: 2.2 Manufacturing Year: | R7: 3.2 Humidity:
B8: 1.3 Date of Scanning: | D8: ='33kV (Main)'!D8 | J8: 2.3 Model: | R8: 3.3 Background (TEV):
B9: 1.4 Time: | D9: ='33kV (Main)'!D9 | J9: 2.4 Last Preventive Maintenance Date:
J10: 2.4 Type of Busbar:
J11: 2.5 Rating (kV):
B13: NO. | C13: PANEL NO. | D13: FEEDER NAME | E13: CABLE TYPE | F13: BREAKER POSITION | G13: BREAKER STATUS | H13: BUSBAR POSITION | I13: LOAD (A) | J13: HEATER (A) WHEN ON / OFF | K13: COMPARTMENT | L13: THERMOGRAPHY | R13: TEV | T13: ULTRASOUND
L14: REF. TEMP (°C) | M14: MAX TEMP (°C) | N14: ∆T | O14: AVG TEMP (°C) | P14: Image No. | Q14: Remarks / Other Defects | R14: Reading (dB) | S14: Pulses / Cycle | T14: Reading (dB) | U14: Type of Characteristic | V14: Remarks / Other Defects
B15: 1 | J15: ON | K15: BREAKER | N15: =IF(M15="","",M15-L15) | O15: =IF(M15="","",((L15+M15)/2)) | S15: =IF(R15<>"", 0, "")
K16: CABLE | N16: =IF(M16="","",M16-L16) | O16: =IF(M16="","",((L16+M16)/2)) | S16: =IF(R16<>"", 0, "")
J17: OFF | K17: BUSBAR (TOP) | N17: =IF(M17="","",M17-L17) | O17: =IF(M17="","",((L17+M17)/2))
J18: =IF(J16="","","0.0") | K18: PT COMPARTMENT | N18: =IF(M18="","",M18-L18) | O18: =IF(M18="","",((L18+M18)/2)) | S18: =IF(R18<>"", 0, "")
K19: CABLE ENTRY | N19: =IF(M19="","",M19-L19) | O19: =IF(M19="","",((L19+M19)/2))
K20: LINK BOX | N20: =IF(M20="","",M20-L20) | O20: =IF(M20="","",((L20+M20)/2))
B21: 2 | J21: ON | K21: BREAKER | N21: =IF(M21="","",M21-L21) | O21: =IF(M21="","",((L21+M21)/2)) | S21: =IF(R21<>"", 0, "")
K22: CABLE | N22: =IF(M22="","",M22-L22) | O22: =IF(M22="","",((L22+M22)/2)) | S22: =IF(R22<>"", 0, "")
J23: OFF | K23: BUSBAR (TOP) | N23: =IF(M23="","",M23-L23) | O23: =IF(M23="","",((L23+M23)/2))
J24: =IF(J22="","","0.0") | K24: PT COMPARTMENT | N24: =IF(M24="","",M24-L24) | O24: =IF(M24="","",((L24+M24)/2)) | S24: =IF(R24<>"", 0, "")
K25: CABLE ENTRY | N25: =IF(M25="","",M25-L25) | O25: =IF(M25="","",((L25+M25)/2))
K26: LINK BOX | N26: =IF(M26="","",M26-L26) | O26: =IF(M26="","",((L26+M26)/2))
B27: 3 | J27: ON | K27: BREAKER | N27: =IF(M27="","",M27-L27) | O27: =IF(M27="","",((L27+M27)/2)) | S27: =IF(R27<>"", 0, "")
K28: CABLE | N28: =IF(M28="","",M28-L28) | O28: =IF(M28="","",((L28+M28)/2)) | S28: =IF(R28<>"", 0, "")
J29: OFF | K29: BUSBAR (TOP) | N29: =IF(M29="","",M29-L29) | O29: =IF(M29="","",((L29+M29)/2))
J30: =IF(J28="","","0.0") | K30: PT COMPARTMENT | N30: =IF(M30="","",M30-L30) | O30: =IF(M30="","",((L30+M30)/2)) | S30: =IF(R30<>"", 0, "")
K31: CABLE ENTRY | N31: =IF(M31="","",M31-L31) | O31: =IF(M31="","",((L31+M31)/2))
K32: LINK BOX | N32: =IF(M32="","",M32-L32) | O32: =IF(M32="","",((L32+M32)/2))
B33: 4 | J33: ON | K33: BREAKER | N33: =IF(M33="","",M33-L33) | O33: =IF(M33="","",((L33+M33)/2)) | S33: =IF(R33<>"", 0, "")
K34: CABLE | N34: =IF(M34="","",M34-L34) | O34: =IF(M34="","",((L34+M34)/2)) | S34: =IF(R34<>"", 0, "")
J35: OFF | K35: BUSBAR (TOP) | N35: =IF(M35="","",M35-L35) | O35: =IF(M35="","",((L35+M35)/2))
J36: =IF(J34="","","0.0") | K36: PT COMPARTMENT | N36: =IF(M36="","",M36-L36) | O36: =IF(M36="","",((L36+M36)/2)) | S36: =IF(R36<>"", 0, "")
K37: CABLE ENTRY | N37: =IF(M37="","",M37-L37) | O37: =IF(M37="","",((L37+M37)/2))
K38: LINK BOX | N38: =IF(M38="","",M38-L38) | O38: =IF(M38="","",((L38+M38)/2))
B39: 5 | J39: ON | K39: BREAKER | N39: =IF(M39="","",M39-L39) | O39: =IF(M39="","",((L39+M39)/2)) | S39: =IF(R39<>"", 0, "")
K40: CABLE | N40: =IF(M40="","",M40-L40) | O40: =IF(M40="","",((L40+M40)/2)) | S40: =IF(R40<>"", 0, "")
J41: OFF | K41: BUSBAR (TOP) | N41: =IF(M41="","",M41-L41) | O41: =IF(M41="","",((L41+M41)/2))
J42: =IF(J40="","","0.0") | K42: PT COMPARTMENT | N42: =IF(M42="","",M42-L42) | O42: =IF(M42="","",((L42+M42)/2)) | S42: =IF(R42<>"", 0, "")
...

Sheet 11kV (Extra)
F2: CBA SWITCHGEAR TEST SHEET (PMU/PPU/SSU) - Page Extra | V2: ='11kV (Main)'!V2
V3: Page No:
V4: CBM Condition
B5: 1.0 Job Details: | J5: 2.0 Switchgear Details: | R5: 3.0 Background Data
B6: 1.1 Substation Name: | D6: ='11kV (Main)'!D6 | J6: 2.1 Manufacture: | L6: ='11kV (Main)'!L6 | M6: ='11kV (Main)'!M6 | R6: 3.1 Background Temp (ɛ = 1.0): | U6: ='33kV (Main)'!U6
B7: 1.2 Substation Location: | D7: ='11kV (Main)'!D7 | J7: 2.2 Manufacturing Year: | L7: ='11kV (Main)'!L7 | R7: 3.2 Humidity: | U7: ='33kV (Main)'!U7
B8: 1.3 Date of Scanning: | D8: ='11kV (Main)'!D8 | J8: 2.3 Model: | L8: ='11kV (Main)'!L8 | R8: 3.3 Background (TEV): | U8: ='33kV (Main)'!U8
B9: 1.4 Time: | D9: ='11kV (Main)'!D9 | J9: 2.4 Last Preventive Maintenance Date: | L9: ='11kV (Main)'!L9
J10: 2.4 Type of Busbar: | L10: ='11kV (Main)'!L10
J11: 2.5 Rating (kV): | L11: ='11kV (Main)'!L11
B13: NO. | C13: PANEL NO. | D13: FEEDER NAME | E13: CABLE TYPE | F13: BREAKER POSITION | G13: BREAKER STATUS | H13: BUSBAR POSITION | I13: LOAD (A) | J13: HEATER (A) WHEN ON / OFF | K13: COMPARTMENT | L13: THERMOGRAPHY | R13: TEV | T13: ULTRASOUND
L14: REF. TEMP (°C) | M14: MAX TEMP (°C) | N14: ∆T | O14: AVG TEMP (°C) | P14: Image No. | Q14: Remarks / Other Defects | R14: Reading (dB) | S14: Pulses / Cycle | T14: Reading (dB) | U14: Type of Characteristic | V14: Remarks / Other Defects
B15: 9 | J15: ON | K15: BREAKER | N15: =IF(M15="","",M15-L15) | O15: =IF(M15="","",((L15+M15)/2)) | S15: =IF(R15<>"", 0, "")
K16: CABLE | N16: =IF(M16="","",M16-L16) | O16: =IF(M16="","",((L16+M16)/2)) | S16: =IF(R16<>"", 0, "")
J17: OFF | K17: BUSBAR (TOP) | N17: =IF(M17="","",M17-L17) | O17: =IF(M17="","",((L17+M17)/2))
J18: =IF(J16="","","0.0") | K18: PT COMPARTMENT | N18: =IF(M18="","",M18-L18) | O18: =IF(M18="","",((L18+M18)/2)) | S18: =IF(R18<>"", 0, "")
K19: CABLE ENTRY | N19: =IF(M19="","",M19-L19) | O19: =IF(M19="","",((L19+M19)/2))
K20: LINK BOX | N20: =IF(M20="","",M20-L20) | O20: =IF(M20="","",((L20+M20)/2))
B21: 10 | J21: ON | K21: BREAKER | N21: =IF(M21="","",M21-L21) | O21: =IF(M21="","",((L21+M21)/2)) | S21: =IF(R21<>"", 0, "")
K22: CABLE | N22: =IF(M22="","",M22-L22) | O22: =IF(M22="","",((L22+M22)/2)) | S22: =IF(R22<>"", 0, "")
J23: OFF | K23: BUSBAR (TOP) | N23: =IF(M23="","",M23-L23) | O23: =IF(M23="","",((L23+M23)/2))
J24: =IF(J22="","","0.0") | K24: PT COMPARTMENT | N24: =IF(M24="","",M24-L24) | O24: =IF(M24="","",((L24+M24)/2)) | S24: =IF(R24<>"", 0, "")
K25: CABLE ENTRY | N25: =IF(M25="","",M25-L25) | O25: =IF(M25="","",((L25+M25)/2))
K26: LINK BOX | N26: =IF(M26="","",M26-L26) | O26: =IF(M26="","",((L26+M26)/2))
B27: 11 | J27: ON | K27: BREAKER | N27: =IF(M27="","",M27-L27) | O27: =IF(M27="","",((L27+M27)/2)) | S27: =IF(R27<>"", 0, "")
K28: CABLE | N28: =IF(M28="","",M28-L28) | O28: =IF(M28="","",((L28+M28)/2)) | S28: =IF(R28<>"", 0, "")
J29: OFF | K29: BUSBAR (TOP) | N29: =IF(M29="","",M29-L29) | O29: =IF(M29="","",((L29+M29)/2))
J30: =IF(J28="","","0.0") | K30: PT COMPARTMENT | N30: =IF(M30="","",M30-L30) | O30: =IF(M30="","",((L30+M30)/2)) | S30: =IF(R30<>"", 0, "")
K31: CABLE ENTRY | N31: =IF(M31="","",M31-L31) | O31: =IF(M31="","",((L31+M31)/2))
K32: LINK BOX | N32: =IF(M32="","",M32-L32) | O32: =IF(M32="","",((L32+M32)/2))
B33: 12 | J33: ON | K33: BREAKER | N33: =IF(M33="","",M33-L33) | O33: =IF(M33="","",((L33+M33)/2)) | S33: =IF(R33<>"", 0, "")
K34: CABLE | N34: =IF(M34="","",M34-L34) | O34: =IF(M34="","",((L34+M34)/2)) | S34: =IF(R34<>"", 0, "")
J35: OFF | K35: BUSBAR (TOP) | N35: =IF(M35="","",M35-L35) | O35: =IF(M35="","",((L35+M35)/2))
J36: =IF(J34="","","0.0") | K36: PT COMPARTMENT | N36: =IF(M36="","",M36-L36) | O36: =IF(M36="","",((L36+M36)/2)) | S36: =IF(R36<>"", 0, "")
K37: CABLE ENTRY | N37: =IF(M37="","",M37-L37) | O37: =IF(M37="","",((L37+M37)/2))
K38: LINK BOX | N38: =IF(M38="","",M38-L38) | O38: =IF(M38="","",((L38+M38)/2))
B39: 13 | J39: ON | K39: BREAKER | N39: =IF(M39="","",M39-L39) | O39: =IF(M39="","",((L39+M39)/2)) | S39: =IF(R39<>"", 0, "")
K40: CABLE | N40: =IF(M40="","",M40-L40) | O40: =IF(M40="","",((L40+M40)/2)) | S40: =IF(R40<>"", 0, "")
J41: OFF | K41: BUSBAR (TOP) | N41: =IF(M41="","",M41-L41) | O41: =IF(M41="","",((L41+M41)/2))
J42: =IF(J40="","","0.0") | K42: PT COMPARTMENT | N42: =IF(M42="","",M42-L42) | O42: =IF(M42="","",((L42+M42)/2)) | S42: =IF(R42<>"", 0, "")
...

Sheet 11kV (Extra) (2)
F2: CBA SWITCHGEAR TEST SHEET (PMU/PPU/SSU) - Page Extra | V2: ='11kV (Main)'!V2
V3: Page No:
V4: CBM Condition
B5: 1.0 Job Details: | J5: 2.0 Switchgear Details: | R5: 3.0 Background Data
B6: 1.1 Substation Name: | D6: ='11kV (Main)'!D6 | J6: 2.1 Manufacture: | L6: ='11kV (Main)'!L6 | M6: ='11kV (Main)'!M6 | R6: 3.1 Background Temp (ɛ = 1.0): | U6: ='33kV (Main)'!U6
B7: 1.2 Substation Location: | D7: ='11kV (Main)'!D7 | J7: 2.2 Manufacturing Year: | L7: ='11kV (Main)'!L7 | R7: 3.2 Humidity: | U7: ='33kV (Main)'!U7
B8: 1.3 Date of Scanning: | D8: ='11kV (Main)'!D8 | J8: 2.3 Model: | L8: ='11kV (Main)'!L8 | R8: 3.3 Background (TEV): | U8: ='33kV (Main)'!U8
B9: 1.4 Time: | D9: ='11kV (Main)'!D9 | J9: 2.4 Last Preventive Maintenance Date: | L9: ='11kV (Main)'!L9
J10: 2.4 Type of Busbar: | L10: ='11kV (Main)'!L10
J11: 2.5 Rating (kV): | L11: ='11kV (Main)'!L11
B13: NO. | C13: PANEL NO. | D13: FEEDER NAME | E13: CABLE TYPE | F13: BREAKER POSITION | G13: BREAKER STATUS | H13: BUSBAR POSITION | I13: LOAD (A) | J13: HEATER (A) WHEN ON / OFF | K13: COMPARTMENT | L13: THERMOGRAPHY | R13: TEV | T13: ULTRASOUND
L14: REF. TEMP (°C) | M14: MAX TEMP (°C) | N14: ∆T | O14: AVG TEMP (°C) | P14: Image No. | Q14: Remarks / Other Defects | R14: Reading (dB) | S14: Pulses / Cycle | T14: Reading (dB) | U14: Type of Characteristic | V14: Remarks / Other Defects
B15: 17 | J15: ON | K15: BREAKER | N15: =IF(M15="","",M15-L15) | O15: =IF(M15="","",((L15+M15)/2)) | S15: =IF(R15<>"", 0, "")
K16: CABLE | N16: =IF(M16="","",M16-L16) | O16: =IF(M16="","",((L16+M16)/2)) | S16: =IF(R16<>"", 0, "")
J17: OFF | K17: BUSBAR (TOP) | N17: =IF(M17="","",M17-L17) | O17: =IF(M17="","",((L17+M17)/2))
J18: =IF(J16="","","0.0") | K18: PT COMPARTMENT | N18: =IF(M18="","",M18-L18) | O18: =IF(M18="","",((L18+M18)/2)) | S18: =IF(R18<>"", 0, "")
K19: CABLE ENTRY | N19: =IF(M19="","",M19-L19) | O19: =IF(M19="","",((L19+M19)/2))
K20: LINK BOX | N20: =IF(M20="","",M20-L20) | O20: =IF(M20="","",((L20+M20)/2))
B21: 18 | J21: ON | K21: BREAKER | N21: =IF(M21="","",M21-L21) | O21: =IF(M21="","",((L21+M21)/2)) | S21: =IF(R21<>"", 0, "")
K22: CABLE | N22: =IF(M22="","",M22-L22) | O22: =IF(M22="","",((L22+M22)/2)) | S22: =IF(R22<>"", 0, "")
J23: OFF | K23: BUSBAR (TOP) | N23: =IF(M23="","",M23-L23) | O23: =IF(M23="","",((L23+M23)/2))
J24: =IF(J22="","","0.0") | K24: PT COMPARTMENT | N24: =IF(M24="","",M24-L24) | O24: =IF(M24="","",((L24+M24)/2)) | S24: =IF(R24<>"", 0, "")
K25: CABLE ENTRY | N25: =IF(M25="","",M25-L25) | O25: =IF(M25="","",((L25+M25)/2))
K26: LINK BOX | N26: =IF(M26="","",M26-L26) | O26: =IF(M26="","",((L26+M26)/2))
B27: 19 | J27: ON | K27: BREAKER | N27: =IF(M27="","",M27-L27) | O27: =IF(M27="","",((L27+M27)/2)) | S27: =IF(R27<>"", 0, "")
K28: CABLE | N28: =IF(M28="","",M28-L28) | O28: =IF(M28="","",((L28+M28)/2)) | S28: =IF(R28<>"", 0, "")
J29: OFF | K29: BUSBAR (TOP) | N29: =IF(M29="","",M29-L29) | O29: =IF(M29="","",((L29+M29)/2))
J30: =IF(J28="","","0.0") | K30: PT COMPARTMENT | N30: =IF(M30="","",M30-L30) | O30: =IF(M30="","",((L30+M30)/2)) | S30: =IF(R30<>"", 0, "")
K31: CABLE ENTRY | N31: =IF(M31="","",M31-L31) | O31: =IF(M31="","",((L31+M31)/2))
K32: LINK BOX | N32: =IF(M32="","",M32-L32) | O32: =IF(M32="","",((L32+M32)/2))
B33: 20 | J33: ON | K33: BREAKER | N33: =IF(M33="","",M33-L33) | O33: =IF(M33="","",((L33+M33)/2)) | S33: =IF(R33<>"", 0, "")
K34: CABLE | N34: =IF(M34="","",M34-L34) | O34: =IF(M34="","",((L34+M34)/2)) | S34: =IF(R34<>"", 0, "")
J35: OFF | K35: BUSBAR (TOP) | N35: =IF(M35="","",M35-L35) | O35: =IF(M35="","",((L35+M35)/2))
J36: =IF(J34="","","0.0") | K36: PT COMPARTMENT | N36: =IF(M36="","",M36-L36) | O36: =IF(M36="","",((L36+M36)/2)) | S36: =IF(R36<>"", 0, "")
K37: CABLE ENTRY | N37: =IF(M37="","",M37-L37) | O37: =IF(M37="","",((L37+M37)/2))
K38: LINK BOX | N38: =IF(M38="","",M38-L38) | O38: =IF(M38="","",((L38+M38)/2))
B39: 21 | J39: ON | K39: BREAKER | N39: =IF(M39="","",M39-L39) | O39: =IF(M39="","",((L39+M39)/2)) | S39: =IF(R39<>"", 0, "")
K40: CABLE | N40: =IF(M40="","",M40-L40) | O40: =IF(M40="","",((L40+M40)/2)) | S40: =IF(R40<>"", 0, "")
J41: OFF | K41: BUSBAR (TOP) | N41: =IF(M41="","",M41-L41) | O41: =IF(M41="","",((L41+M41)/2))
J42: =IF(J40="","","0.0") | K42: PT COMPARTMENT | N42: =IF(M42="","",M42-L42) | O42: =IF(M42="","",((L42+M42)/2)) | S42: =IF(R42<>"", 0, "")
...

Sheet 11kV (Extra) (3)
F2: CBA SWITCHGEAR TEST SHEET (PMU/PPU/SSU) - Page Extra | V2: ='11kV (Main)'!V2
V3: Page No:
V4: CBM Condition
B5: 1.0 Job Details: | J5: 2.0 Switchgear Details: | R5: 3.0 Background Data
B6: 1.1 Substation Name: | D6: ='11kV (Main)'!D6 | J6: 2.1 Manufacture: | L6: ='11kV (Main)'!L6 | M6: ='11kV (Main)'!M6 | R6: 3.1 Background Temp (ɛ = 1.0): | U6: ='33kV (Main)'!U6
B7: 1.2 Substation Location: | D7: ='11kV (Main)'!D7 | J7: 2.2 Manufacturing Year: | L7: ='11kV (Main)'!L7 | R7: 3.2 Humidity: | U7: ='33kV (Main)'!U7
B8: 1.3 Date of Scanning: | D8: ='11kV (Main)'!D8 | J8: 2.3 Model: | L8: ='11kV (Main)'!L8 | R8: 3.3 Background (TEV): | U8: ='33kV (Main)'!U8
B9: 1.4 Time: | D9: ='11kV (Main)'!D9 | J9: 2.4 Last Preventive Maintenance Date: | L9: ='11kV (Main)'!L9
J10: 2.4 Type of Busbar: | L10: ='11kV (Main)'!L10
J11: 2.5 Rating (kV): | L11: ='11kV (Main)'!L11
B13: NO. | C13: PANEL NO. | D13: FEEDER NAME | E13: CABLE TYPE | F13: BREAKER POSITION | G13: BREAKER STATUS | H13: BUSBAR POSITION | I13: LOAD (A) | J13: HEATER (A) WHEN ON / OFF | K13: COMPARTMENT | L13: THERMOGRAPHY | R13: TEV | T13: ULTRASOUND
L14: REF. TEMP (°C) | M14: MAX TEMP (°C) | N14: ∆T | O14: AVG TEMP (°C) | P14: Image No. | Q14: Remarks / Other Defects | R14: Reading (dB) | S14: Pulses / Cycle | T14: Reading (dB) | U14: Type of Characteristic | V14: Remarks / Other Defects
B15: 25 | J15: ON | K15: BREAKER | N15: =IF(M15="","",M15-L15) | O15: =IF(M15="","",((L15+M15)/2)) | S15: =IF(R15<>"", 0, "")
K16: CABLE | N16: =IF(M16="","",M16-L16) | O16: =IF(M16="","",((L16+M16)/2)) | S16: =IF(R16<>"", 0, "")
J17: OFF | K17: BUSBAR (TOP) | N17: =IF(M17="","",M17-L17) | O17: =IF(M17="","",((L17+M17)/2))
J18: =IF(J16="","","0.0") | K18: PT COMPARTMENT | N18: =IF(M18="","",M18-L18) | O18: =IF(M18="","",((L18+M18)/2)) | S18: =IF(R18<>"", 0, "")
K19: CABLE ENTRY | N19: =IF(M19="","",M19-L19) | O19: =IF(M19="","",((L19+M19)/2))
K20: LINK BOX | N20: =IF(M20="","",M20-L20) | O20: =IF(M20="","",((L20+M20)/2))
B21: 26 | J21: ON | K21: BREAKER | N21: =IF(M21="","",M21-L21) | O21: =IF(M21="","",((L21+M21)/2)) | S21: =IF(R21<>"", 0, "")
K22: CABLE | N22: =IF(M22="","",M22-L22) | O22: =IF(M22="","",((L22+M22)/2)) | S22: =IF(R22<>"", 0, "")
J23: OFF | K23: BUSBAR (TOP) | N23: =IF(M23="","",M23-L23) | O23: =IF(M23="","",((L23+M23)/2))
J24: =IF(J22="","","0.0") | K24: PT COMPARTMENT | N24: =IF(M24="","",M24-L24) | O24: =IF(M24="","",((L24+M24)/2)) | S24: =IF(R24<>"", 0, "")
K25: CABLE ENTRY | N25: =IF(M25="","",M25-L25) | O25: =IF(M25="","",((L25+M25)/2))
K26: LINK BOX | N26: =IF(M26="","",M26-L26) | O26: =IF(M26="","",((L26+M26)/2))
B27: 27 | J27: ON | K27: BREAKER | N27: =IF(M27="","",M27-L27) | O27: =IF(M27="","",((L27+M27)/2)) | S27: =IF(R27<>"", 0, "")
K28: CABLE | N28: =IF(M28="","",M28-L28) | O28: =IF(M28="","",((L28+M28)/2)) | S28: =IF(R28<>"", 0, "")
J29: OFF | K29: BUSBAR (TOP) | N29: =IF(M29="","",M29-L29) | O29: =IF(M29="","",((L29+M29)/2))
J30: =IF(J28="","","0.0") | K30: PT COMPARTMENT | N30: =IF(M30="","",M30-L30) | O30: =IF(M30="","",((L30+M30)/2)) | S30: =IF(R30<>"", 0, "")
K31: CABLE ENTRY | N31: =IF(M31="","",M31-L31) | O31: =IF(M31="","",((L31+M31)/2))
K32: LINK BOX | N32: =IF(M32="","",M32-L32) | O32: =IF(M32="","",((L32+M32)/2))
B33: 28 | J33: ON | K33: BREAKER | N33: =IF(M33="","",M33-L33) | O33: =IF(M33="","",((L33+M33)/2)) | S33: =IF(R33<>"", 0, "")
K34: CABLE | N34: =IF(M34="","",M34-L34) | O34: =IF(M34="","",((L34+M34)/2)) | S34: =IF(R34<>"", 0, "")
J35: OFF | K35: BUSBAR (TOP) | N35: =IF(M35="","",M35-L35) | O35: =IF(M35="","",((L35+M35)/2))
J36: =IF(J34="","","0.0") | K36: PT COMPARTMENT | N36: =IF(M36="","",M36-L36) | O36: =IF(M36="","",((L36+M36)/2)) | S36: =IF(R36<>"", 0, "")
K37: CABLE ENTRY | N37: =IF(M37="","",M37-L37) | O37: =IF(M37="","",((L37+M37)/2))
K38: LINK BOX | N38: =IF(M38="","",M38-L38) | O38: =IF(M38="","",((L38+M38)/2))
B39: 29 | J39: ON | K39: BREAKER | N39: =IF(M39="","",M39-L39) | O39: =IF(M39="","",((L39+M39)/2)) | S39: =IF(R39<>"", 0, "")
K40: CABLE | N40: =IF(M40="","",M40-L40) | O40: =IF(M40="","",((L40+M40)/2)) | S40: =IF(R40<>"", 0, "")
J41: OFF | K41: BUSBAR (TOP) | N41: =IF(M41="","",M41-L41) | O41: =IF(M41="","",((L41+M41)/2))
J42: =IF(J40="","","0.0") | K42: PT COMPARTMENT | N42: =IF(M42="","",M42-L42) | O42: =IF(M42="","",((L42+M42)/2)) | S42: =IF(R42<>"", 0, "")
...

Sheet TX
B2: Company Name | G2: CBM SUBSTATION TEST SHEET (PMU/PPU/SSU) | AC2: Test Sheet No: | AD2: Page No:
AC4: CBM Condition
B5: 1. Substation Details: | G5: 2. Transformer Details:
B6: 1.1 | C6: Substation Name: | G6: TX 1 | I6: MODEL: | K6: TX 2 | L6: MODEL: | N6: TX 3 | O6: MODEL: | Q6: TX 4 | R6: MODEL: | T6: LOCAL TX | V6: MODEL:
G7: 2.1 Manufacturer: | K7: 2.1 Manufacturer: | N7: 2.1 Manufacturer: | Q7: 2.1 Manufacturer: | T7: 2.1 Manufacturer:
G8: 2.2 Rating (MVA): | K8: 2.2 Rating (MVA): | N8: 2.2 Rating (MVA): | Q8: 2.2 Rating (MVA): | T8: 2.2 Rating (KVA):
G9: 2.3 Serial No. : | K9: 2.3 Serial No. : | N9: 2.3 Serial No. : | Q9: 2.3 Serial No. : | T9: 2.3 Serial No. :
B10: TRANSFORMER
B11: DETAILS | J11: ULTRASOUND | R11: THERMOGRAPHY | AB11: Remarks
B12: No. | C12: TX No. | F12: Load ( A) | H12: Cable Type | J12: HV Cable | N12: LV Cable | R12: HV Cable | W12: LV Cable
J13: Reading (dB) | K13: Type Charc. | M13: File | N13: Reading (dB) | O13: Type Charc. | Q13: File | R13: Ref. Temp (°C) | S13: Max Temp (°C) | T13: Defect ∆T | U13: Avg Temp (°C) | V13: File | W13: Ref. Temp (°C) | X13: Max Temp (°C) | Y13: Defect ∆T | Z13: Avg Temp (°C) | AA13: File
B14: 1 | C14: TX 1 | T14: =IF(S14="","",S14-R14) | U14: =IF(S14="","",((R14+S14)/2)) | Y14: =IF(X14="","",X14-W14) | Z14: =IF(X14="","",((W14+X14)/2))
B17: 2 | C17: TX 2 | T17: =IF(S17="","",S17-R17) | U17: =IF(S17="","",((R17+S17)/2)) | Y17: =IF(X17="","",X17-W17) | Z17: =IF(X17="","",((W17+X17)/2))
B20: 3 | C20: TX 3 | T20: =IF(S20="","",S20-R20) | U20: =IF(S20="","",((R20+S20)/2)) | Y20: =IF(X20="","",X20-W20) | Z20: =IF(X20="","",((W20+X20)/2))
B23: 4 | C23: TX4 | T23: =IF(S23="","",S23-R23) | U23: =IF(S23="","",((R23+S23)/2)) | Y23: =IF(X23="","",X23-W23) | Z23: =IF(X23="","",((W23+X23)/2))
B26: 5 | C26: Local TX | T26: =IF(S26="","",S26-R26) | U26: =IF(S26="","",((R26+S26)/2)) | Y26: =IF(X26="","",X26-W26) | Z26: =IF(X26="","",((W26+X26)/2))
B30: DETAILS | F30: THERMOGRAPHY
B31: No | C31: TX No | F31: Marshalling Kiosk | L31: Conservator Tank | R31: Body | X31: Cooling Fin | AC31: Remarks
F32: Ref. Temp (°C) | G32: Max Temp (°C) | H32: Defect ∆T | I32: Avg Temp (°C) | J32: File | L32: Ref. Temp (°C) | M32: Max Temp (°C) | N32: Defect ∆T | O32: Avg Temp (°C) | P32: File | R32: Ref. Temp (°C) | S32: Max Temp (°C) | T32: Defect ∆T | U32: Avg Temp (°C) | V32: File | X32: Ref. Temp (°C) | Y32: Max Temp (°C) | Z32: Defect ∆T | AA32: Avg Temp (°C) | AB32: File
B33: 1 | C33: TX 1 | H33: =IF(G33="","",G33-F33) | I33: =IF(G33="","",((F33+G33)/2)) | N33: =IF(M33="","",M33-L33) | O33: =IF(M33="","",((L33+M33)/2)) | T33: =IF(S33="","",S33-R33) | U33: =IF(S33="","",((R33+S33)/2)) | Z33: =IF(Y33="","",Y33-X33) | AA33: =IF(Y33="","",((X33+Y33)/2))
B36: 2 | C36: TX 2 | H36: =IF(G36="","",G36-F36) | I36: =IF(G36="","",((F36+G36)/2)) | N36: =IF(M36="","",M36-L36) | O36: =IF(M36="","",((L36+M36)/2)) | T36: =IF(S36="","",S36-R36) | U36: =IF(S36="","",((R36+S36)/2)) | Z36: =IF(Y36="","",Y36-X36) | AA36: =IF(Y36="","",((X36+Y36)/2))
B39: 3 | C39: TX 3 | H39: =IF(G39="","",G39-F39) | I39: =IF(G39="","",((F39+G39)/2)) | N39: =IF(M39="","",M39-L39) | O39: =IF(M39="","",((L39+M39)/2)) | T39: =IF(S39="","",S39-R39) | U39: =IF(S39="","",((R39+S39)/2)) | Z39: =IF(Y39="","",Y39-X39) | AA39: =IF(Y39="","",((X39+Y39)/2))
B42: 4 | C42: TX 4 | H42: =IF(G42="","",G42-F42) | I42: =IF(G42="","",((F42+G42)/2)) | N42: =IF(M42="","",M42-L42) | O42: =IF(M42="","",((L42+M42)/2)) | T42: =IF(S42="","",S42-R42) | U42: =IF(S42="","",((R42+S42)/2)) | Z42: =IF(Y42="","",Y42-X42) | AA42: =IF(Y42="","",((X42+Y42)/2))
B45: 5 | C45: LOCAL TX | H45: =IF(G45="","",G45-F45) | I45: =IF(G45="","",((F45+G45)/2)) | N45: =IF(M45="","",M45-L45) | O45: =IF(M45="","",((L45+M45)/2)) | T45: =IF(S45="","",S45-R45) | U45: =IF(S45="","",((R45+S45)/2)) | Z45: =IF(Y45="","",Y45-X45) | AA45: =IF(Y45="","",((X45+Y45)/2))
B49: LV DISTRIBUTION BOARD/FEEDER PILLAR/OTHERS
B51: Rating (A):
B52: Serial No.:
B53: Type:
B54: Manufacturer:
B56: LVDB / FP | D56: INC 1 | F56: INC 2 | G56: INC 3 | H56: F1 | I56: F2 | J56: F3 | K56: F4 | L56: F5 | M56: F6 | N56: F7 | O56: F8
B57: Cable Type
B58: Cable Size
B60: No | C60: LVDB / FP | D60: Cable Type | F60: Cable Size | G60: Ref. Temp (°C) | H60: Max Temp (°C) | I60: Defect ∆T | J60: Avg Temp (°C) | K60: File | L60: Load (A) | P60: Remarks
L61: Red | M61: Yellow | N61: Blue | O61: Neutral
B62: 1
B64: 2
S65: ULTRASOUND Type Characteristic
B66: 3 | S66: A | T66: Arcing
S67: T | T67: Tracking
B68: 4 | S68: C | T68: Corona
...

Sheet Visual Inspection
D1: VISUAL INSPECTION CHECKLIST FOR PMU/PPU/SSU
B3: Substation Name | L3: GPS:
B4: Date
A6: On-line Visual Audits and Diagnostic Tests :
A7: 1 | B7: Verifications of Switchgear External Condition | L7: Remarks
B9: 1.1 No water marks on the panels | H9: YES | I9: NO | J9: N/A
B11: 1.2 All covers and door bolted properly | H11: YES | I11: NO | J11: N/A
B13: 1.3 Opening and interpanel gaps sealed | H13: YES | I13: NO | J13: N/A
A15: 2 | B15: Verification of Switchgear Internal Components and Compartments
B17: 2.1 No dust ingress, wind blown dust penetration | H17: YES | I17: NO | J17: N/A
B19: 2.2 No gas leakages detected in GIS switchgear ( i.e check SF6 level) | H19: YES | I19: NO | J19: N/A
B21: 2.3 No oil leakage for OCBs. i.e. check oil level | H21: YES | I21: NO | J21: N/A
B23: 2.4 Heaters at every compartment are functioning and in good condition | H23: YES | I23: NO | J23: N/A
A25: 3 | B25: Switchgear & Substation Earthing
B27: 3.1 Proper earth connection between all switchgear | H27: YES | I27: NO | J27: N/A
B29: 3.2 Proper earth connection to common earth | H29: YES | I29: NO | J29: N/A
B31: 3.3 Proper Switchgear earthing installation. i.e copper / stay wire / stollen / disconnected | H31: YES | I31: NO | J31: N/A
A34: 4 | B34: Power Transformer Condition
B36: 4.1 No leaks at Power Transformer | H36: YES | I36: NO | J36: N/A
B38: 4.2 Adequate oil at Main Tank. i.e. to check oil level at main tank | H38: YES | I38: NO | J38: N/A
B40: 4.3 Adequate oil at OLTC Tank. i.e. to check oil level at OLTC tank | H40: YES | I40: NO | J40: N/A
B42: 4.4 Cooling Fan are in place and functioning or fuse blown/faulty MCB | H42: YES | I42: NO | J42: N/A
B44: 4.5 No anormalities or any indication of corrosion or leaks at HV and LV cable box | H44: YES | I44: NO | J44: N/A
B47: 4.6 Transformer tail earthing is in proper and good condition | H47: YES | I47: NO | J47: N/A
B49: 4.7 Cable entry openings properly sealed. | H49: YES | I49: NO | J49: N/A
B51: 4.8 Chequer plate provided. | H51: YES | I51: NO | J51: N/A
B53: 4.9 Proper Transformer earthing installation. i.e copper / stay wire / stollen / disconnected | H53: YES | I53: NO | J53: N/A
A57: 5 | B57: NER Condition
B59: 5.1 Proper NER earthing installation. i.e copper / stay wire / stollen / disconnected | H59: YES | I59: NO | J59: N/A
B61: 5.2 Proper earth bars and links | H61: YES | I61: NO | J61: N/A
B62: (Note:If there have any defect occur, record in testsheet under remarks thermography)
A64: 6 | B64: Field Cable Verifications
B66: 6.1 Power cables properly supported i.e power cables / power transformer / local transformer | H66: YES | I66: NO | J66: N/A
B69: 6.2 Power cable opening properly sealed. i.e cable entry sealed | H69: YES | I69: NO | J69: N/A
A71: 7 | B71: Building
B73: 7.1 Good roof condition i.e. no leakage | H73: YES | I73: NO | J73: N/A
B75: 7.2 Good battery charger condition (110VDC) | H75: YES | I75: NO | J75: N/A
A77: 8 | B77: Other Findings :
M81: FE EXP. DATE:
A82: Tested by (Name & Signature): | D82: {{signvendor}} | H82: TNB Supervisor / Engineer (Name & Signature): | M82: {{signtnb}}
...

Sheet RAW DATA
B1: START | C1: END
A2: IR
A3: DG
