Workbook

Sheet PCE Testsheet
W2: CBM CONDITION | Y2: NORMAL
A3: DISTRIBUTION SUBSTATION (PCE) CBA TEST SHEET
A4: STATE / AREA: | C4: JOHOR / JOHOR BAHRU | J4: DATE | W4: FUNCTIONAL LOCATION:
A5: PE NAME: | J5: TIME IN / OUT | R5: / | W5: JJBU/PCE/J
A6: V.I REF. NO | C6: =Y1 -> 0 | J6: TEV BACK GROUND / HUMIDITY | Q6: dB | R6: / | U6: % | W6: BACKGROUND TEMP : °C
A7: SWITCHGEAR
A8: DETAIL | J8: TEMPERATURE | Q8: ULTRASOUND | T8: TEV | W8: REMARK
A9: NO. | B9: FDR. NO | C9: FEEDER NAME | E9: STATUS (TRIP / CLOSE) | F9: LOAD (A) | G9: CABLE TYPE/SIZE | H9: HEATER (A) | I9: SERIAL NO (ONLY BREAKER & OLU) | J9: COMP | K9: Tmin (°C) | L9: Tmax (°C) | M9: ΔT | N9: Avg (°C) | O9: FILE | P9: REMARKS | Q9: dB | R9: FILE | S9: TYPE CHAR. | T9: dB | U9: PULSE/ CYCLE | V9: TYPE CHAR.
A10: 1 | J10: CABLE | M10: =IF(L10="","",L10-K10) | N10: =IF(L10="","",((L10+K10)/2)) | U10: =IF(T10<>"", 0, "")
J11: BREAKER | M11: =IF(L11="","",L11-K11) | N11: =IF(L11="","",((L11+K11)/2)) | U11: =IF(T11<>"", 0, "")
J12: TOP PANEL | M12: =IF(L12="","",L12-K12) | N12: =IF(L12="","",((L12+K12)/2)) | U12: =IF(T12<>"", 0, "")
J13: PT | M13: =IF(L13="","",L13-K13) | N13: =IF(L13="","",((L13+K13)/2)) | U13: =IF(T13<>"", 0, "")
A14: 2 | J14: CABLE | M14: =IF(L14="","",L14-K14) | N14: =IF(L14="","",((L14+K14)/2)) | U14: =IF(T14<>"", 0, "")
J15: BREAKER | M15: =IF(L15="","",L15-K15) | N15: =IF(L15="","",((L15+K15)/2)) | U15: =IF(T15<>"", 0, "")
J16: TOP PANEL | M16: =IF(L16="","",L16-K16) | N16: =IF(L16="","",((L16+K16)/2)) | U16: =IF(T16<>"", 0, "")
J17: PT | M17: =IF(L17="","",L17-K17) | N17: =IF(L17="","",((L17+K17)/2)) | U17: =IF(T17<>"", 0, "")
A18: 3 | J18: CABLE | M18: =IF(L18="","",L18-K18) | N18: =IF(L18="","",((L18+K18)/2)) | U18: =IF(T18<>"", 0, "")
J19: BREAKER | M19: =IF(L19="","",L19-K19) | N19: =IF(L19="","",((L19+K19)/2)) | U19: =IF(T19<>"", 0, "")
J20: TOP PANEL | M20: =IF(L20="","",L20-K20) | N20: =IF(L20="","",((L20+K20)/2)) | U20: =IF(T20<>"", 0, "")
J21: PT | M21: =IF(L21="","",L21-K21) | N21: =IF(L21="","",((L21+K21)/2)) | U21: =IF(T21<>"", 0, "")
A22: 4 | J22: CABLE | M22: =IF(L22="","",L22-K22) | N22: =IF(L22="","",((L22+K22)/2)) | U22: =IF(T22<>"", 0, "")
J23: BREAKER | M23: =IF(L23="","",L23-K23) | N23: =IF(L23="","",((L23+K23)/2)) | U23: =IF(T23<>"", 0, "")
J24: TOP PANEL | M24: =IF(L24="","",L24-K24) | N24: =IF(L24="","",((L24+K24)/2)) | U24: =IF(T24<>"", 0, "")
J25: PT | M25: =IF(L25="","",L25-K25) | N25: =IF(L25="","",((L25+K25)/2)) | U25: =IF(T25<>"", 0, "")
A26: OVERVIEW | J26: CABLE
J27: BREAKER
J28: TOP PANEL
J29: PT
A30: LOCAL TRANSFORMER
A31: DETAILS | F31: THERMOGRAHY | K31: ULTRASOUND | M31: DETAILS | Q31: THERMOGRAHY | W31: ULTRASOUND
A32: TX ID | B32: SERIAL NO | C32: CABLE TYPE/SIZE | D32: REMARK | E32: COMP. | F32: Tmin(°C) | G32: Tmax(°C) | H32: ΔT | I32: Avg (°C) | J32: FILE | K32: dB | L32: TYPE CHAR. | M32: TX ID | N32: SERIAL NO | O32: CABLE TYPE/SIZE | P32: COMP. | Q32: Tmin(°C) | R32: Tmax(°C) | S32: ΔT | T32: Avg (°C) | U32: FILE | V32: dB | W32: FILE | X32: TYPE CHAR. | Y32: REMARKS
A33: TX1 | B33: =IF('PCE VI'!O18="","",'PCE VI'!O18) | E33: HT CABLE | H33: =IF(G33="","",G33-F33) | I33: =IF(G33="","",((G33+F33)/2)) | M33: TX3 | N33: =IF('PCE VI'!O20="","",'PCE VI'!O20) | P33: HT CABLE | S33: =IF(R33="","",R33-Q33) | T33: =IF(R33="","",((R33+Q33)/2))
E34: HT BUSHING | H34: =IF(G34="","",G34-F34) | I34: =IF(G34="","",((G34+F34)/2)) | P34: HT BUSHING | S34: =IF(R34="","",R34-Q34) | T34: =IF(R34="","",((R34+Q34)/2))
E35: LV CABLE | H35: =IF(G35="","",G35-F35) | I35: =IF(G35="","",((G35+F35)/2)) | P35: LV CABLE | S35: =IF(R35="","",R35-Q35) | T35: =IF(R35="","",((R35+Q35)/2))
E36: LV BUSHING | H36: =IF(G36="","",G36-F36) | I36: =IF(G36="","",((G36+F36)/2)) | P36: LV BUSHING | S36: =IF(R36="","",R36-Q36) | T36: =IF(R36="","",((R36+Q36)/2))
E37: BODY | H37: =IF(G37="","",G37-F37) | I37: =IF(G37="","",((G37+F37)/2)) | P37: BODY | S37: =IF(R37="","",R37-Q37) | T37: =IF(R37="","",((R37+Q37)/2))
A38: TX2 | B38: =IF('PCE VI'!O19="","",'PCE VI'!O19) | E38: HT CABLE | H38: =IF(G38="","",G38-F38) | I38: =IF(G38="","",((G38+F38)/2)) | M38: TX4 | N38: =IF('PCE VI'!O20="","",'PCE VI'!O20) | P38: HT CABLE | S38: =IF(R38="","",R38-Q38) | T38: =IF(R38="","",((R38+Q38)/2))
E39: HT BUSHING | H39: =IF(G39="","",G39-F39) | I39: =IF(G39="","",((G39+F39)/2)) | P39: HT BUSHING | S39: =IF(R39="","",R39-Q39) | T39: =IF(R39="","",((R39+Q39)/2))
E40: LV CABLE | H40: =IF(G40="","",G40-F40) | I40: =IF(G40="","",((G40+F40)/2)) | P40: LV CABLE | S40: =IF(R40="","",R40-Q40) | T40: =IF(R40="","",((R40+Q40)/2))
E41: LV BUSHING | H41: =IF(G41="","",G41-F41) | I41: =IF(G41="","",((G41+F41)/2)) | P41: LV BUSHING | S41: =IF(R41="","",R41-Q41) | T41: =IF(R41="","",((R41+Q41)/2))
...

Sheet PCE VI
M1: TYPE | O1: ='PCE Testsheet'!Y1 -> 0
B3: VISUAL INSPECTION CHECKLIST FOR 11kV SUBSTATION
B5: DATE: | C5: ='PCE Testsheet'!P4 -> 0
B6: P/E Name (ERMS): | C6: =IF('PCE Testsheet'!C5="","",'PCE Testsheet'!C5) | J6: F/L NO (ERMS): | K6: =IF('PCE Testsheet'!W5="","",'PCE Testsheet'!W5) -> JJBU/PCE/J
B7: P/E Name (SITE): | J7: F/L NO (SITE):
B8: GPS Coordinate:
B9: PCE Type: | C9: INDOOR | F9: OUTDOOR | H9: COMPACT | J9: ATTACH BUILDING | L9: PAT | N9: OTHER
B10: PCE Area | C10: NORMAL | F10: INDUSTRIAL | H10: COASTAL
B11: Switcgear Type 1: | C11: RMU OIL | F11: RMU SF6 | H11: MRMU | J11: VCB | L11: OCB | N11: OTHER
B12: Manufacturer/Model:
B13: Switchgear Manufactured Date: | H13: Switchgear Rating : | M13: RMU SF6 / OIL S/N :
B14: Switcgear Type 2: | C14: RMU OIL | F14: RMU SF6 | H14: MRMU | J14: VCB | L14: OCB
B15: Manufacturer/Modal:
B16: Switchgear Manufactured Date: | H16: Switchgear Rating : | M16: RMU SF6 / OIL S/N :
B17: No. of Transformer:
B18: Tx 1: | C18: Type | E18: KVA | G18: Construction Yr: | J18: Manufacturer: | N18: S/N :
B19: Tx 2: | C19: Type | E19: KVA | G19: Construction Yr: | J19: Manufacturer: | N19: S/N :
B20: Tx 3: | C20: Type | E20: KVA | G20: Construction Yr: | J20: Manufacturer: | N20: S/N :
B21: Tx 4: | C21: Type | E21: KVA | G21: Construction Yr: | J21: Manufacturer: | N21: S/N :
B22: KEJANGGALAN
B23: 1. Signboard: | D23: Good | F23: Not Good | H23: Remarks | I23: =IF(AND(ISBLANK(E23),ISBLANK(G23)),"N/A","") -> N/A
B24: 2. Earth connection: | D24: Good | F24: Not Good | H24: Remarks | I24: =IF(AND(ISBLANK(E24),ISBLANK(G24)),"N/A","") -> N/A
B25: 3. EFI Functioning: | D25: Good | F25: Not Good | H25: Remarks | I25: =IF(AND(ISBLANK(E25),ISBLANK(G25)),"N/A","") -> N/A
B26: 4. Heater Functioning: | D26: Good | F26: Not Good | H26: Remarks | I26: =IF(AND(ISBLANK(E26),ISBLANK(G26)),"N/A","") -> N/A
B27: 5. Labelling @Switchgear: | D27: Good | F27: Not Good | H27: Remarks | I27: =IF(AND(ISBLANK(E27),ISBLANK(G27)),"N/A","") -> N/A
B28: 6. Labelling @ LVDB: | D28: Good | F28: Not Good | H28: Remarks | I28: =IF(AND(ISBLANK(E28),ISBLANK(G28)),"N/A","") -> N/A
B29: 7. Gas Pressure: | D29: Good | F29: Not Good | H29: Remarks | I29: =IF(AND(ISBLANK(E29),ISBLANK(G29)),"N/A","") -> N/A
B30: 8. Tx Guard: | D30: YES | F30: NO | H30: Remarks | I30: =IF(AND(ISBLANK(E30),ISBLANK(G30)),"N/A","") -> N/A
B31: 9. Tx Oil Level (conservator tank): | D31: Good | F31: Not Good | H31: Remarks | I31: =IF(AND(ISBLANK(E31),ISBLANK(G31)),"N/A","") -> N/A
B32: 10. Tx Oil Leak: | D32: YES | F32: NO | H32: Remarks | I32: =IF(AND(ISBLANK(E32),ISBLANK(G32)),"N/A","") -> N/A
B33: 11. Tx Bushing: | D33: Good | F33: Not Good | H33: Remarks | I33: =IF(AND(ISBLANK(E33),ISBLANK(G33)),"N/A","") -> N/A
B34: 12. Top Demand Indicator (@LVDB): | D34: Good | F34: Not Good | H34: Remarks | I34: =IF(AND(ISBLANK(E34),ISBLANK(G34)),"N/A","") -> N/A
... B41: 19. Roof Condition: | D41: Good | F41: Not Good | H41: Remarks | I41: =IF(AND(ISBLANK(E41),ISBLANK(G41)),"N/A","") -> N/A
B42: 20. Fire Fighting | D42: Valid | F42: Expired | H42: Remarks | I42: Expiry Date: | L42: No. of missing portable : | N42: -
B43: 21. Fence/door condition: | D43: Good | F43: Not Good | H43: Remarks | I43: =IF(AND(ISBLANK(E43),ISBLANK(G43)),"N/A","") -> N/A
B44: 22. Cleanliness/Bushes: | D44: YES | F44: NO | H44: Remarks | I44: =IF(AND(ISBLANK(E44),ISBLANK(G44)),"N/A","") -> N/A
B45: 23. Vandalisme | D45: YES | F45: NO | H45: Remarks | I45: =IF(AND(ISBLANK(E45),ISBLANK(G45)),"N/A","") -> N/A
B46: 24. Other Findings:
B49: Tested by (Name & Signature) : | D49: {{signvendor}} | H49: TNB Supervisor / Engineer (Name & Signature) : | M49: {{signtnb}}
B51: Date : | H51: Date :
...

Sheet RAW DATA
B1: START | C1: END
A2: IR
A3: DG

Sheet vi_library
A1: SUBSTATION_TYPE | B1: CHECKMARK
A2: INDOOR | B2: ✅
A3: OUTDOOR
A4: PAT
A5: COMPACT
A6: ATTACHED BUILDING
A7: INDOOR/COMPACT
A8: OUTDOOR/COMPACT

Sheet substation_library
A1: AREA | B1: STATE
A2: JOHOR BAHRU | B2: JOHOR

Sheet equipment_library
A1: SWITCHGEAR_TYPE | B1: CB_POSITION_RMU | C1: CB_POSITION_VCB | D1: BUSBAR_POSITION | E1: CABLE_TYPE | F1: SWG_MANUFACTURER | G1: SWG_MODEL | H1: SWG_RATING | I1: TX_MANUFACTURER | J1: TX_MODEL | K1: TX_RATING | L1: TX_AREA | M1: LV_MANUFACTURER | N1: LV_MODEL | O1: LV_RATING | P1: BATT_MANUFACTURER | Q1: BATT_MODEL
A2: RMU SF6 | B2: CLOSE | C2: SERVICE/CLOSE | D2: MAIN | E2: XLPE | H2: 6.6kV | J2: H/S | K2: 1000kVA | L2: OVERVIEW | N2: DIN TYPE | O2: 1600A | P2: BERKAT INSAF | Q2: SEB100-30-10
A3: MRMU SF6 | B3: TRIP | C3: SERVICE/TRIP | D3: RESERVE | E3: PILC | H3: 12kV | J3: C/T | K3: 750kVA | L3: OVERVIEW TOP | N3: J-SLOTTED | O3: 1000A | P3: SUNPOWER
A4: RMU OIL | C4: TEST/TRIP | D4: MAIN/RESERVE | E4: N/A | H4: 24kV | K4: 500kVA | L4: HV BUSHING | O4: 800A
A5: VCB | C5: RACK OUT | D5: N/A | E5: NOT ACCESSIBLE | H5: 36kV | K5: 300kVA | L5: HV CABLE | O5: 400A
A6: GIS | K6: 100kVA | L6: HV CABLE SPLIT | O6: N/A
A7: ACB | K7: N/A | L7: LV BUSHING
A8: PAT | K8: NOT ACCESSIBLE | L8: LV CABLE
