Workbook

Sheet PCE Testsheet
W2: CBM CONDITION | Y2: NORMAL
A3: DISTRIBUTION SUBSTATION (PCE) CBA TEST SHEET
A4: STATE / AREA: | C4: JOHOR / JOHOR BAHRU | J4: DATE | W4: FUNCTIONAL LOCATION:
A5: PE NAME: | J5: TIME IN / OUT | R5: / | W5: JJBU/PCE/J
A6: V.I REF. NO | C6: =Y1 -> 0 | J6: TEV BACK GROUND / HUMIDITY | Q6: dB | R6: / | U6: % | W6: BACKGROUND TEMP : °C
A7: SWITCHGEAR
A8: DETAIL | J8: TEMPERATURE | Q8: ULTRASOUND | T8: TEV | W8: REMARK
A9: NO. | B9: FDR. NO | C9: FEEDER NAME | E9: STATUS (TRIP / CLOSE) | F9: LOAD (A) | G9: CABLE TYPE/SIZE | H9: HEATER (A) | I9: SERIAL NO (ONLY BREAKER & OLU) | J9: COMP | K9: Tmin (°C) | L9: Tmax (°C) | M9: ΔT | N9: Avg (°C) | O9: FILE | P9: REMARKS | Q9: dB | R9: FILE | S9: TYPE CHAR. | T9: dB | U9: PULSE/ CYCLE | V9: TYPE CHAR.
A10: 1 | J10: CABLE | M10: =IF(L10="","",L10-K10) | N10: =IF(L10="","",((L10+K10)/2)) | U10: =IF(T10<>"", 0, "")
J11: BREAKER | M11: =IF(L11="","",L11-K11) | N11: =IF(L11="","",((L11+K11)/2)) | U11: =IF(T11<>"", 0, "")
J12: TOP PANEL | M12: =IF(L12="","",L12-K12) | N12: =IF(L12="","",((L12+K12)/2)) | U12: =IF(T12<>"", 0, "")
J13: PT | M13: =IF(L13="","",L13-K13) | N13: =IF(L13="","",((L13+K13)/2)) | U13: =IF(T13<>"", 0, "")
A14: 2 | J14: CABLE | M14: =IF(L14="","",L14-K14) | N14: =IF(L14="","",((L14+K14)/2)) | U14: =IF(T14<>"", 0, "")
J15: BREAKER | M15: =IF(L15="","",L15-K15) | N15: =IF(L15="","",((L15+K15)/2)) | U15: =IF(T15<>"", 0, "")
J16: TOP PANEL | M16: =IF(L16="","",L16-K16) | N16: =IF(L16="","",((L16+K16)/2)) | U16: =IF(T16<>"", 0, "")
J17: PT | M17: =IF(L17="","",L17-K17) | N17: =IF(L17="","",((L17+K17)/2)) | U17: =IF(T17<>"", 0, "")
A18: 3 | J18: CABLE | M18: =IF(L18="","",L18-K18) | N18: =IF(L18="","",((L18+K18)/2)) | U18: =IF(T18<>"", 0, "")
J19: BREAKER | M19: =IF(L19="","",L19-K19) | N19: =IF(L19="","",((L19+K19)/2)) | U19: =IF(T19<>"", 0, "")
J20: TOP PANEL | M20: =IF(L20="","",L20-K20) | N20: =IF(L20="","",((L20+K20)/2)) | U20: =IF(T20<>"", 0, "")
J21: PT | M21: =IF(L21="","",L21-K21) | N21: =IF(L21="","",((L21+K21)/2)) | U21: =IF(T21<>"", 0, "")
A22: 4 | J22: CABLE | M22: =IF(L22="","",L22-K22) | N22: =IF(L22="","",((L22+K22)/2)) | U22: =IF(T22<>"", 0, "")
J23: BREAKER | M23: =IF(L23="","",L23-K23) | N23: =IF(L23="","",((L23+K23)/2)) | U23: =IF(T23<>"", 0, "")
J24: TOP PANEL | M24: =IF(L24="","",L24-K24) | N24: =IF(L24="","",((L24+K24)/2)) | U24: =IF(T24<>"", 0, "")
J25: PT | M25: =IF(L25="","",L25-K25) | N25: =IF(L25="","",((L25+K25)/2)) | U25: =IF(T25<>"", 0, "")
A26: OVERVIEW | J26: CABLE
J27: BREAKER
J28: TOP PANEL
J29: PT
A30: LOCAL TRANSFORMER
A31: DETAILS | F31: THERMOGRAHY | K31: ULTRASOUND | M31: DETAILS | Q31: THERMOGRAHY | W31: ULTRASOUND
A32: TX ID | B32: SERIAL NO | C32: CABLE TYPE/SIZE | D32: REMARK | E32: COMP. | F32: Tmin(°C) | G32: Tmax(°C) | H32: ΔT | I32: Avg (°C) | J32: FILE | K32: dB | L32: TYPE CHAR. | M32: TX ID | N32: SERIAL NO | O32: CABLE TYPE/SIZE | P32: COMP. | Q32: Tmin(°C) | R32: Tmax(°C) | S32: ΔT | T32: Avg (°C) | U32: FILE | V32: dB | W32: FILE | X32: TYPE CHAR. | Y32: REMARKS
A33: TX1 | B33: =IF('PCE VI'!O18="","",'PCE VI'!O18) | E33: HT CABLE | H33: =IF(G33="","",G33-F33) | I33: =IF(G33="","",((G33+F33)/2)) | M33: TX3 | N33: =IF('PCE VI'!O20="","",'PCE VI'!O20) | P33: HT CABLE | S33: =IF(R33="","",R33-Q33) | T33: =IF(R33="","",((R33+Q33)/2))
E34: HT BUSHING | H34: =IF(G34="","",G34-F34) | I34: =IF(G34="","",((G34+F34)/2)) | P34: HT BUSHING | S34: =IF(R34="","",R34-Q34) | T34: =IF(R34="","",((R34+Q34)/2))
E35: LV CABLE | H35: =IF(G35="","",G35-F35) | I35: =IF(G35="","",((G35+F35)/2)) | P35: LV CABLE | S35: =IF(R35="","",R35-Q35) | T35: =IF(R35="","",((R35+Q35)/2))
E36: LV BUSHING | H36: =IF(G36="","",G36-F36) | I36: =IF(G36="","",((G36+F36)/2)) | P36: LV BUSHING | S36: =IF(R36="","",R36-Q36) | T36: =IF(R36="","",((R36+Q36)/2))
E37: BODY | H37: =IF(G37="","",G37-F37) | I37: =IF(G37="","",((G37+F37)/2)) | P37: BODY | S37: =IF(R37="","",R37-Q37) | T37: =IF(R37="","",((R37+Q37)/2))
A38: TX2 | B38: =IF('PCE VI'!O19="","",'PCE VI'!O19) | E38: HT CABLE | H38: =IF(G38="","",G38-F38) | I38: =IF(G38="","",((G38+F38)/2)) | M38: TX4 | N38: =IF('PCE VI'!O21="","",'PCE VI'!O21) | P38: HT CABLE | S38: =IF(R38="","",R38-Q38) | T38: =IF(R38="","",((R38+Q38)/2))
E39: HT BUSHING | H39: =IF(G39="","",G39-F39) | I39: =IF(G39="","",((G39+F39)/2)) | P39: HT BUSHING | S39: =IF(R39="","",R39-Q39) | T39: =IF(R39="","",((R39+Q39)/2))
E40: LV CABLE | H40: =IF(G40="","",G40-F40) | I40: =IF(G40="","",((G40+F40)/2)) | P40: LV CABLE | S40: =IF(R40="","",R40-Q40) | T40: =IF(R40="","",((R40+Q40)/2))
E41: LV BUSHING | H41: =IF(G41="","",G41-F41) | I41: =IF(G41="","",((G41+F41)/2)) | P41: LV BUSHING | S41: =IF(R41="","",R41-Q41) | T41: =IF(R41="","",((R41+Q41)/2))
...

Sheet PCE VI
M1: TYPE | O1: ='PCE Testsheet'!Y1 -> 0
B3: VISUAL INSPECTION CHECKLIST FOR 11kV SUBSTATION
B5: DATE: | C5: ='PCE Testsheet'!P4 -> 0
B6: P/E Name (ERMS): | C6: =IF('PCE Testsheet'!C5="","",'PCE Testsheet'!C5) | J6: F/L NO (ERMS): | K6: =IF('PCE Testsheet'!W5="","",'PCE Testsheet'!W5) -> JJBU/PCE/J
B7: P/E Name (SITE): | J7: F/L NO (SITE):
B8: GPS Coordinate:
B9: PCE Type: | C9: INDOOR | F9: OUTDOOR | H9: COMPACT | J9: ATTACH BUILDING | L9: PAT | N9: OTHER
B10: PCE Area | C10: NORMAL | F10: INDUSTRIAL | H10: COASTAL
B11: Switcgear Type 1: | C11: RMU OIL | F11: RMU SF6 | H11: MRMU | J11: VCB | L11: OCB | N11: OTHER
B12: Manufacturer/Model:
B13: Switchgear Manufactured Date: | H13: Switchgear Rating : | M13: RMU SF6 / OIL S/N :
B14: Switcgear Type 2: | C14: RMU OIL | F14: RMU SF6 | H14: MRMU | J14: VCB | L14: OCB | N14: OTHER
B15: Manufacturer/Modal:
B16: Switchgear Manufactured Date: | H16: Switchgear Rating : | M16: RMU SF6 / OIL S/N :
B17: No. of Transformer:
B18: Tx 1: | C18: Type | E18: KVA | G18: Construction Yr: | J18: Manufacturer: | N18: S/N :
B19: Tx 2: | C19: Type | E19: KVA | G19: Construction Yr: | J19: Manufacturer: | N19: S/N :
B20: Tx 3: | C20: Type | E20: KVA | G20: Construction Yr: | J20: Manufacturer: | N20: S/N :
B21: Tx 4: | C21: Type | E21: KVA | G21: Construction Yr: | J21: Manufacturer: | N21: S/N :
B22: KEJANGGALAN
B23: 1. Signboard: | D23: Good | F23: Not Good | H23: Remarks | I23: =IF(AND(ISBLANK(E23),ISBLANK(G23)),"N/A","") -> N/A
B24: 2. Earth connection: | D24: Good | F24: Not Good | H24: Remarks | I24: =IF(AND(ISBLANK(E24),ISBLANK(G24)),"N/A","") -> N/A
B25: 3. EFI Functioning: | D25: Good | F25: Not Good | H25: Remarks | I25: =IF(AND(ISBLANK(E25),ISBLANK(G25)),"N/A","") -> N/A
B26: 4. Heater Functioning: | D26: Good | F26: Not Good | H26: Remarks | I26: =IF(AND(ISBLANK(E26),ISBLANK(G26)),"N/A","") -> N/A
B27: 5. Labelling @Switchgear: | D27: Good | F27: Not Good | H27: Remarks | I27: =IF(AND(ISBLANK(E27),ISBLANK(G27)),"N/A","") -> N/A
B28: 6. Labelling @ LVDB: | D28: Good | F28: Not Good | H28: Remarks | I28: =IF(AND(ISBLANK(E28),ISBLANK(G28)),"N/A","") -> N/A
B29: 7. Gas Pressure: | D29: Good | F29: Not Good | H29: Remarks | I29: =IF(AND(ISBLANK(E29),ISBLANK(G29)),"N/A","") -> N/A
B30: 8. Tx Guard: | D30: YES | F30: NO | H30: Remarks | I30: =IF(AND(ISBLANK(E30),ISBLANK(G30)),"N/A","") -> N/A
B31: 9. Tx Oil Level (conservator tank): | D31: Good | F31: Not Good | H31: Remarks | I31: =IF(AND(ISBLANK(E31),ISBLANK(G31)),"N/A","") -> N/A
B32: 10. Tx Oil Leak: | D32: YES | F32: NO | H32: Remarks | I32: =IF(AND(ISBLANK(E32),ISBLANK(G32)),"N/A","") -> N/A
B33: 11. Tx Bushing: | D33: Good | F33: Not Good | H33: Remarks | I33: =IF(AND(ISBLANK(E33),ISBLANK(G33)),"N/A","") -> N/A
B34: 12. Top Demand Indicator (@LVDB): | D34: Good | F34: Not Good | H34: Remarks | I34: =IF(AND(ISBLANK(E34),ISBLANK(G34)),"N/A","") -> N/A
... B41: 19. Roof Condition: | D41: Good | F41: Not Good | H41: Remarks | I41: =IF(AND(ISBLANK(E41),ISBLANK(G41)),"N/A","") -> N/A
B42: 20. Fire Fighting | D42: Valid | F42: Expired | H42: Remarks | I42: Expiry Date: | L42: No. of missing portable : | N42: -
B43: 21. Fence/door condition: | D43: Good | F43: Not Good | H43: Remarks | I43: =IF(AND(ISBLANK(E43),ISBLANK(G43)),"N/A","") -> N/A
B44: 22. Cleanliness/Bushes: | D44: YES | F44: NO | H44: Remarks | I44: =IF(AND(ISBLANK(E44),ISBLANK(G44)),"N/A","") -> N/A
B45: 23. Vandalisme | D45: YES | F45: NO | H45: Remarks | I45: =IF(AND(ISBLANK(E45),ISBLANK(G45)),"N/A","") -> N/A
B46: 24. Other Findings:
B49: Tested by (Name & Signature) : | D49: {{signvendor}} | H49: TNB Supervisor / Engineer (Name & Signature) : | M49: {{signtnb}}
B51: Date : | H51: Date :
...

Sheet ASSET_11
A1: ASSET 11KV | B1: SCOPE IR | C1: SCOPE IR DETAILS | D1: SCOPE IR RATE | E1: SCOPE IR+US | F1: SCOPE IR+US DETAILS | G1: SCOPE IR+US RATE | H1: FULL SCOPE | I1: FULL SCOPE DETAILS | J1: FULL SCOPE RATE
A2: PCE | B2: 2010323000 | C2: SCAN,THERMO VT,PE | D2: 250 | E2: 2010323030 | F2: SCAN,THERMO & ULTRASOUND VT,PE | G2: 315 | H2: 2010323038 | I2: SCAN,THERMO & USD & TEV VT,PE | J2: 395
A3: PCE (NO RMU) | B3: 2010323000 | C3: SCAN,THERMO VT,PE | D3: 250 | E3: 2010323030 | F3: SCAN,THERMO & ULTRASOUND VT,PE | G3: 315 | H3: - | I3: - | J3: -
A4: PCE 33 | B4: 2010323000 | C4: SCAN,THERMO VT,PE | D4: 250 | E4: 2010323030 | F4: SCAN,THERMO & ULTRASOUND VT,PE | G4: 315 | H4: 2010323038 | I4: SCAN,THERMO & USD & TEV VT,PE | J4: 395
A5: PCE 33 (NO RMU) | B5: 2010323000 | C5: SCAN,THERMO VT,PE | D5: 250 | E5: 2010323030 | F5: SCAN,THERMO & ULTRASOUND VT,PE | G5: 315 | H5: - | I5: - | J5: -
A6: PAT | B6: 2010323000 | C6: SCAN,THERMO VT,PE | D6: 250 | E6: 2010323030 | F6: SCAN,THERMO & ULTRASOUND VT,PE | G6: 315 | H6: - | I6: - | J6: -
A7: PAT+RMU | B7: 2010323000 | C7: SCAN,THERMO VT,PE | D7: 250 | E7: 2010323030 | F7: SCAN,THERMO & ULTRASOUND VT,PE | G7: 315 | H7: 2010323038 | I7: SCAN,THERMO & USD & TEV VT,PE | J7: 395
A8: PAT 33 | B8: 2010323000 | C8: SCAN,THERMO VT,PE | D8: 250 | E8: 2010323030 | F8: SCAN,THERMO & ULTRASOUND VT,PE | G8: 315 | H8: - | I8: - | J8: -
A9: PAT 33+RMU | B9: 2010323000 | C9: SCAN,THERMO VT,PE | D9: 250 | E9: 2010323030 | F9: SCAN,THERMO & ULTRASOUND VT,PE | G9: 315 | H9: 2010323038 | I9: SCAN,THERMO & USD & TEV VT,PE | J9: 395
A10: SS | B10: 2010323000 | C10: SCAN,THERMO VT,PE | D10: 250 | E10: 2010323030 | F10: SCAN,THERMO & ULTRASOUND VT,PE | G10: 315 | H10: 2010323038 | I10: SCAN,THERMO & USD & TEV VT,PE | J10: 395
A11: CS | B11: 2010323000 | C11: SCAN,THERMO VT,PE | D11: 250 | E11: 2010323030 | F11: SCAN,THERMO & ULTRASOUND VT,PE | G11: 315 | H11: 2010323038 | I11: SCAN,THERMO & USD & TEV VT,PE | J11: 395
A12: PE VCB =< 8 | B12: 2010323000 | C12: SCAN,THERMO VT,PE | D12: 250 | E12: 2010323030 | F12: SCAN,THERMO & ULTRASOUND VT,PE | G12: 315 | H12: 2010323038 | I12: SCAN,THERMO & USD & TEV VT,PE | J12: 395
A13: PE VCB > 8 | B13: 2010323051 | C13: SCAN,THERMO VT,PE 11KV,> 8VCB | D13: 473.9 | E13: 2010323054 | F13: SCAN,THERMO & USD VT,PE 11KV,> 8VCB | G13: 670.8 | H13: 2010323056 | I13: SCAN,THERMO, USD & TEV VT,PE 11KV,> 8VCB | J13: 1217.6
A14: SSU =< 8 | B14: 2010323000 | C14: SCAN,THERMO VT,PE | D14: 250 | E14: 2010323030 | F14: SCAN,THERMO & ULTRASOUND VT,PE | G14: 315 | H14: 2010323038 | I14: SCAN,THERMO & USD & TEV VT,PE | J14: 395
A15: SSU > 8 | B15: 2010323051 | C15: SCAN,THERMO VT,PE 11KV,> 8VCB | D15: 473.9 | E15: 2010323054 | F15: SCAN,THERMO & USD VT,PE 11KV,> 8VCB | G15: 670.8 | H15: 2010323056 | I15: SCAN,THERMO, USD & TEV VT,PE 11KV,> 8VCB | J15: 1217.6
A16: LINK | B16: - | C16: - | D16: - | E16: - | F16: - | G16: - | H16: - | I16: - | J16: -
A17: DECOMM | B17: - | C17: - | D17: - | E17: - | F17: - | G17: - | H17: - | I17: - | J17: -
A18: UPGRADE PROCESS | B18: - | C18: - | D18: - | E18: - | F18: - | G18: - | H18: - | I18: - | J18: -
A19: CANT ACCESS
A20: DUPLICATE
A21: DISMANTLE

Sheet Model
A1: Column1 | B1: Model | C1: ITEM | D1: TAMCO | E1: INDKOM | F1: INFRAKOMAS | G1: ABB | H1: TOSHIBA | I1: EPE | J1: F&G | K1: ALSTOM | L1: AREVA | M1: SIEMENS | N1: MERLIN GERIN | O1: TOPRANK | P1: LUCY | Q1: TSG | R1: MITSUBISHI | S1: ORMAZABAL | T1: SCHNEIDER | U1: FUJI | V1: SSE | W1: IIESB | X1: RANHILL | Y1: S&S POWER | Z1: S&S AMPSTON | AA1: S&S TOPRANK | AB1: ANZECO | AC1: AEG | AD1: GEC | AE1: TOSHIBA TOPRANK | AF1: BHARAT HEAVY | AG1: AR | AH1: ASEA | AI1: NINGBO TIANAN | AJ1: MEIDEN | AK1: HITACHI | AL1: HI-VAC | AM1: BERKAT INSAF | AN1: SUNPOWER TECHNOLOGIES | AO1: ACEC | AP1: ASEA LEPPER | AQ1: CHANG CHING | AR1: ELIN | AS1: EMO-OHRID | AT1: EWT | AU1: IEO TRANSFORMATOREN BREDA | AV1: KIRLOSKAR | AW1: LKH | AX1: MINEL-TRAFO | AY1: MITSUBISHI_1 | AZ1: MTM | BA1: NACC | BB1: NEW KOREA | BC1: ONAN | BD1: PAUWEL TRAFO | BE1: SCHNEIDER_2 | BF1: SGB | BG1: T.M.C.-S.A. | BH1: TOSHIBA_3 | BI1: WODEN
A2: 5 | B2: MODEL | C2: 3AH5 103-1 | D2: ~VCB~ | E2: CB 112 JMW12 KV | F2: 3S+1F | G2: CEI 17-1 | H2: GT16-12 | I2: 12A20 | J2: ZZT | K2: WSB 6/36-2/627 | L2: WSB | M2: 8DA10 | N2: RN2C | O2: 2L1T | P2: AEGIS | Q2: BJ12 | R2: V-10F-20 | S2: GA2K1TS | T2: RN2c | V2: VRN2A | Y2: HVV-12 | AA2: ID3L | AB2: CSGO | AD2: CVG-20F-25 | AJ2: BF-12 | AK2: CVG-20F-25 | AL2: CVG-20F-25 | AM2: SEB100-30-10 | AO2: HERMETICALLY SEAL | AP2: HERMETICALLY SEAL | AQ2: HERMETICALLY SEAL | AR2: HERMETICALLY SEAL | AS2: HERMETICALLY SEAL | AT2: HERMETICALLY SEAL | AU2: HERMETICALLY SEAL | AV2: HERMETICALLY SEAL | AW2: HERMETICALLY SEAL | AX2: HERMETICALLY SEAL | AY2: HERMETICALLY SEAL | AZ2: HERMETICALLY SEAL | BA2: HERMETICALLY SEAL | BB2: HERMETICALLY SEAL | BC2: HERMETICALLY SEAL | BD2: DRY | BE2: HERMETICALLY SEAL | BF2: HERMETICALLY SEAL | BG2: HERMETICALLY SEAL | BH2: HERMETICALLY SEAL | BI2: HERMETICALLY SEAL
A3: 6 | B3: MODEL | C3: 3AH5 104-2 | D3: GV3 | E3: INS 24 RCB | F3: 2S+1F | G3: GV3M/18 | H3: GT18-40.5 | I3: 12A25 | J3: INS24 | K3: SBV4 | M3: 8DB10 | N3: RN2 | O3: HV-12 | P3: VRN6A | Q3: CPG | R3: ~LTX/DTX~ | S3: CA6303K1TS | T3: NE-IQI | V3: VRN6A | Y3: HHV-12 | AD3: CVG-20F-25A | AK3: CVG-20F-25A | AO3: CONSERVATOR TANK | AP3: CONSERVATOR TANK | AQ3: CONSERVATOR TANK | AR3: CONSERVATOR TANK | AS3: CONSERVATOR TANK | AT3: CONSERVATOR TANK | AU3: CONSERVATOR TANK | AV3: CONSERVATOR TANK | AW3: CONSERVATOR TANK | AX3: CONSERVATOR TANK | AY3: CONSERVATOR TANK | AZ3: CONSERVATOR TANK | BA3: CONSERVATOR TANK | BB3: CONSERVATOR TANK | BC3: CONSERVATOR TANK | BE3: CONSERVATOR TANK | BF3: CONSERVATOR TANK | BG3: CONSERVATOR TANK | BH3: CONSERVATOR TANK | BI3: CONSERVATOR TANK
A4: 3 | B4: MODEL | C4: 3AH5546 | D4: GV30M25 | E4: CB JMW 112 | G4: HA2/ZC | H4: HV-12 | I4: 36A25 | J4: ZZTT | M4: 8DJ20.10 | N4: 6 | O4: HV-36 | P4: VRN2A | Q4: GA6302K1TS | R4: HERMETICALLY SEAL | S4: 2K2TS | T4: RM6 | AD4: CVG-10F-20 | AK4: CVG-10F-20
A5: 7 | B5: MODEL | C5: 3HA5 104-2 | D5: GV30M25B | E5: INS24 | G5: HD4 | H5: VT15-12 | I5: 36A25-1 | M5: 8DJH | O5: ID2L+2T | Q5: CPG.0 | R5: CONSERVATOR TANK | T5: ~LTX/DTX~
A6: 9 | B6: MODEL | C6: 8BK-88 | D6: GV30M25D | G6: IVBG | H6: VT18-40.5 | I6: 3S | M6: 8DJH RRT | O6: ID3L+1T | T6: HERMETICALLY SEAL
A7: 4 | B7: MODEL | C7: 8BK88 K18 | D7: GV30NM25 | G7: SACE | H7: VY | I7: BGA-32 | M7: 8DJH20 | O7: VH3D | T7: CONSERVATOR TANK
A8: 10 | B8: MODEL | C8: 8BK-88E | D8: GV30P25 | G8: SACE HA3 / BEU-37-12-26 | H8: X6N49S-40.5(Z) | I8: BGA-36 | M8: 8DJH20.71
A9: 2 | B9: MODEL | C9: 8BK-88K12 | D9: GV30P25D | G9: SACE HAZ | H9: X6N94S-40.5(Z) | I9: CCC | M9: 3AH4945
A10: 8 | B10: MODEL | C10: 8DA10 | D10: GV3D | G10: SACE HAZ/ZC | H10: XBN498-40.5(Z) | I10: CCTI
A11: 11 | B11: MODEL | C11: 8DB | D11: VH3 | G11: VD4 | H11: XCN498 | I11: DGA-32
A12: 12 | B12: MODEL | C12: 8DB10 | D12: VH3D | G12: VD4E | H12: XCN75 | I12: HICLAD 100
A13: 13 | B13: MODEL | C13: 8DJH RRT | D13: VHID | G13: VD4E 1206 P20 | H13: XGN | I13: HICLAD 10D
A14: 1 | B14: MODEL | C14: NXPLUS C | D14: VHIH | G14: VD4X | H14: XGN498-40.5(Z) | I14: V-32 DBB
A15: 14 | B15: MODEL | D15: VK10J20D | G15: VD4X 3612-25 | H15: XGN49S | I15: VB7-25/8D
A16: 15 | B16: MODEL | D16: VK10J20H | G16: VD4X 4012-25 | H16: XGN49S-40.5 | I16: VFT-12
A17: 25 | B17: MODEL | D17: VK10J25D | G17: VDX 3612-25 | H17: XGN49S-40.5(Z) | I17: VFT-12-106
A18: 26 | B18: MODEL | D18: VK10J25H | G18: VMAX | H18: XGN75-12(Z) | I18: VFT-12D
A19: 27 | B19: MODEL | D19: VK10P25 | G19: ZV2 | H19: ~LTX/DTX~ | I19: VGA-32
A20: 28 | B20: MODEL | D20: VK10P25D | G20: ZV2.3 | H20: HERMETICALLY SEAL | I20: VH32
A21: 29 | B21: MODEL | D21: VK10P25DT | H21: CONSERVATOR TANK | I21: VJ-22
A22: 30 | B22: MODEL | D22: VK10P25H | I22: VJ-32
A23: 31 | B23: MODEL | D23: VK12 | I23: VJ-32 DBB
A24: 32 | B24: MODEL | D24: VK12D | I24: VPT-12
A25: 33 | B25: MODEL | D25: VV30M25D | I25: VRN29
A26: 35 | B26: MODEL | D26: VW-20M25
A27: 36 | B27: MODEL | D27: VY-30M
A28: 37 | B28: MODEL | D28: VY30M25D
A29: 38 | B29: MODEL | D29: VY30M25DT
A30: 39 | B30: MODEL | D30: VY30M26ST
A31: 41 | B31: MODEL | D31: VY30P25D
A32: 24 | B32: MODEL | D32: VY-30P25D
A33: 34 | B33: MODEL | D33: WSB
A34: 40 | B34: MODEL | D34: ~RMU~
A35: 16 | B35: MODEL | D35: FALCONBETA
A36: 17 | B36: MODEL | D36: GR1
A37: 18 | B37: MODEL
A38: 19 | B38: MODEL
A39: 20 | B39: MODEL
A40: 21 | B40: MODEL
...

Sheet Brand
A1: Column1 | B1: EQUIPMENT | C1: VCB 33kV | D1: VCB 22kV | E1: VCB 11kV | F1: VCB 6.6kV | G1: GIS 33kV | H1: GIS 22kV | I1: GIS 11kV | J1: RMU SF6 | K1: RMU OIL | L1: CABLE SWG | M1: PTX | N1: CABLE PTX | O1: LTX/DTX | P1: CABLE LTX/DTX | Q1: FP (J) | R1: LVDB | S1: FP (D) | T1: CABLE LVDB/FP | U1: LINK BOX | V1: BREAKER (SW YARD) | W1: ISOLATOR (SW YARD) | X1: CT (SW YARD) | Y1: BLACK BOX | Z1: BATTERY CHARGER | AA1: EARTHING | AB1: ISOLATOR LINK | AC1: PIN ISOLATOR | AD1: DROPOUT FUSE | AE1: LBS | AF1: LIGHTNING ARRESTOR | AG1: AUTO RECLOSER | AH1: PT AR
A2: 1 | B2: BRAND | C2: ABB | D2: ABB | E2: ABB | F2: ABB | G2: ABB | H2: SIEMENS | I2: ABB | J2: INDKOM | K2: TAMCO | L2: XLPE | M2: ABB | N2: XLPE | O2: ACEC | P2: XLPE | Q2: EWT | R2: EWT | S2: EWT | T2: XLPE | V2: GEC | Z2: SUN POWER
A3: 2 | B3: BRAND | C3: EPE | D3: EPE | E3: AMPSTON | F3: EPE | G3: AEG | H3: TAMCO | I3: EPE | J3: TAMCO | L3: PILC | M3: ABB ELEKTRIK SANAYI | N3: PILC | O3: ASEA LEPPER | P3: PILC | Q3: ABB | R3: ABB | S3: ABB | T3: PILC | Z3: BERKAT INSAF
A4: 3 | B4: BRAND | C4: FUJI | D4: GEC | E4: EPE | F4: GEC | G4: AREVA | I4: GEC | J4: LUCY | M4: ACEC | O4: CHANG CHING | Q4: AEI | R4: AEI | S4: AEI
A5: 4 | B5: BRAND | C5: GEC | D5: HITACHI | E5: FUJI | F5: HITACHI | G5: EPE | I5: ITEM | J5: SSE | M5: AM SGB | O5: ELIN | Q5: ALAF CEKAL | R5: ALAF CEKAL | S5: ALAF CEKAL
A6: 5 | B6: BRAND | C6: ITEM | D6: HI-VAC | E6: GEC | F6: TAMCO | G6: ITEM | I6: SIEMENS | J6: SCHNEIDER | M6: BHARAT | O6: EMO-OHRID | Q6: ALGEBRA | R6: ALGEBRA | S6: ALGEBRA
A7: 6 | B7: BRAND | C7: MITSUBISHI | D7: TAMCO | E7: ITEM | F7: S&S AMPSTON | G7: RANHILL | I7: TAMCO | J7: FALCON BETA | M7: CRAIOVA | O7: EWT | Q7: ALTENA | R7: ALTENA | S7: ALTENA
A8: 7 | B8: BRAND | C8: S&S AMPSTON | D8: TOSHIBA | E8: MEIDEN | F8: S&S POWER | G8: SIEMENS | I8: TOPRANK | J8: TOPRANK | M8: CRAIOVA ROMANIA | O8: IEO TRANSFORMATOREN BREDA | Q8: AMPSTON | R8: AMPSTON | S8: AMPSTON
A9: 8 | B9: BRAND | C9: S&S POWER | E9: MITSUBISHI | F9: S&S TOPRANK | G9: TAMCO | I9: TOSHIBA | J9: EPE | M9: ELECTRA | O9: KIRLOSKAR | Q9: ANZECO POWER | R9: ANZECO POWER | S9: ANZECO POWER
A10: 9 | B10: BRAND | C10: S&S TOPRANK | E10: RANHILL | G10: TOSHIBA | I10: TSG | J10: ORMAZABAL | M10: ELECTRO PUTERE | O10: LKH | Q10: BONAR LONG | R10: BONAR LONG | S10: BONAR LONG
A11: 10 | B11: BRAND | C11: SIEMENS | E11: S&S AMPSTON | G11: TSG | J11: F&G | M11: FUJI ELECTRIC | O11: MINEL-TRAFO | Q11: E.A.M | R11: E.A.M | S11: E.A.M
A12: 11 | B12: BRAND | C12: TAMCO | E12: S&S POWER | J12: MERLIN GERIN | M12: HEFEI | O12: MITSUBISHI | Q12: EPE | R12: EPE | S12: EPE
A13: 12 | B13: BRAND | C13: TOPRANK | E13: S&S TOPRANK | J13: ABB | M13: HERMANN MATERN | O13: MTM | Q13: GEC | R13: GEC | S13: GEC
A14: 13 | B14: BRAND | C14: TOSHIBA | E14: SIEMENS | J14: INFRAKOMAS | M14: HYUNDAI | O14: NACC | Q14: INDKOM | R14: INDKOM | S14: INDKOM
A15: 14 | B15: BRAND | E15: TAMCO | M15: LEEEC | O15: NEW KOREA | Q15: ITEM | R15: ITEM | S15: ITEM
A16: 15 | B16: BRAND | E16: TOPRANK | M16: LIAOYANG | O16: PAUWEL TRAFO | Q16: JEAN MULLER | R16: JEAN MULLER | S16: JEAN MULLER
A17: 16 | B17: BRAND | E17: TOSHIBA | M17: MITSUBISHI | O17: SCHNEIDER | Q17: MTM | R17: MTM | S17: MTM
A18: 17 | B18: BRAND | E18: TSG | M18: MTM | O18: SGB | Q18: POLYPHASE | R18: POLYPHASE | S18: POLYPHASE
A19: 18 | B19: BRAND | E19: VEI | M19: NANCHANG | O19: T.M.C.-S.A. | Q19: PRONUTEC | R19: PRONUTEC | S19: PRONUTEC
A20: 19 | B20: BRAND | M20: RADE KONCAR | O20: TOSHIBA | Q20: PSB | R20: PSB | S20: PSB
A21: 20 | B21: BRAND | M21: SAVIGLIANO | O21: WODEN | Q21: SCHNEIDER | R21: SCHNEIDER | S21: SCHNEIDER
A22: 21 | B22: BRAND | M22: SHENYANG | Q22: SSE | R22: SSE | S22: SSE
A23: 22 | B23: BRAND | M23: SHIHLIN | Q23: TAMCO | R23: TAMCO | S23: TAMCO
A24: 23 | B24: BRAND | M24: TAKAOKA | Q24: TAMCO CUTLER HAMMER | R24: TAMCO CUTLER HAMMER | S24: TAMCO CUTLER HAMMER
A25: 24 | B25: BRAND | M25: TUR INDIA | Q25: TAN & LOW | R25: TAN & LOW | S25: TAN & LOW
A26: 25 | B26: BRAND | M26: WILSON | Q26: TEKNIK | R26: TEKNIK | S26: TEKNIK
A27: 26 | B27: BRAND | M27: XI'AN | Q27: TENAGA | R27: TENAGA | S27: TENAGA
A28: 27 | B28: BRAND | Q28: TOPRANK | R28: TOPRANK | S28: TOPRANK
A29: 28 | B29: BRAND | Q29: TOSHIBA | R29: TOSHIBA | S29: TOSHIBA
A30: 29 | B30: BRAND | Q30: WELL PRESTIGE | R30: WELL PRESTIGE | S30: WELL PRESTIGE
A31: 30 | B31: BRAND | Q31: WOODEN | R31: WOODEN | S31: WOODEN
A32: 31 | B32: BRAND
A33: 32 | B33: BRAND
A34: 33 | B34: BRAND
A35: 34 | B35: BRAND
A36: 35 | B36: BRAND
A37: 36 | B37: BRAND
A38: 37 | B38: BRAND
A39: 38 | B39: BRAND
A40: 39 | B40: BRAND
...

Sheet RAW DATA
B1: START | C1: END
A2: IR
A3: DG

Sheet vi_library
A1: SUBSTATION_TYPE | B1: CHECKMARK
A2: INDOOR | B2: ✅
A3: OUTDOOR
A4: PAT
A5: COMPACT
A6: ATTACHED BUILDING
A7: INDOOR/COMPACT
A8: OUTDOOR/COMPACT

Sheet substation_library
A1: AREA | B1: STATE
A2: JOHOR BAHRU | B2: JOHOR

Sheet equipment_library
A1: SWITCHGEAR_TYPE | B1: CB_POSITION_RMU | C1: CB_POSITION_VCB | D1: BUSBAR_POSITION | E1: CABLE_TYPE | F1: SWG_MANUFACTURER | G1: SWG_MODEL | H1: SWG_RATING | I1: TX_MANUFACTURER | J1: TX_MODEL | K1: TX_RATING | L1: TX_AREA | M1: LV_MANUFACTURER | N1: LV_MODEL | O1: LV_RATING | P1: BATT_MANUFACTURER | Q1: BATT_MODEL | R1: VCB 33kV | S1: VCB 22kV | T1: VCB 11kV | U1: VCB 6.6kV | V1: GIS 33kV | W1: GIS 22kV | X1: GIS 11kV | Y1: RMU SF6 | Z1: RMU OIL | AA1: CABLE SWG | AB1: PTX | AC1: CABLE PTX | AD1: LTX/DTX | AE1: CABLE LTX/DTX | AF1: FP (J) | AG1: LVDB | AH1: FP (D) | AI1: CABLE LVDB/FP | AJ1: LINK BOX | AK1: BREAKER (SW YARD) | AL1: ISOLATOR (SW YARD) | AM1: CT (SW YARD) | AN1: BLACK BOX | AO1: BATTERY CHARGER | AP1: EARTHING | AQ1: ISOLATOR LINK | AR1: PIN ISOLATOR | AS1: DROPOUT FUSE | AT1: LBS | AU1: LIGHTNING ARRESTOR | AV1: AUTO RECLOSER | AW1: PT AR
A2: RMU SF6 | B2: CLOSE | C2: CLOSE | D2: MAIN | E2: XLPE | H2: 6.6kV | J2: H/S | K2: 1000kVA | L2: OVERVIEW | N2: DIN TYPE | O2: 1600A | P2: BERKAT INSAF | Q2: SEB100-30-10 | R2: ABB | S2: ABB | T2: ABB | U2: ABB | V2: ABB | W2: SIEMENS | X2: ABB | Y2: INDKOM | Z2: TAMCO | AA2: XLPE | AB2: ABB | AC2: XLPE | AD2: ACEC | AE2: XLPE | AF2: EWT | AG2: EWT | AH2: EWT | AI2: XLPE | AK2: GEC | AO2: SUN POWER
A3: MRMU SF6 | B3: TRIP | C3: TRIP | D3: RESERVE | E3: PILC | H3: 12kV | J3: C/T | K3: 750kVA | L3: OVERVIEW TOP | N3: J-SLOTTED | O3: 1000A | P3: SUNPOWER | R3: EPE | S3: EPE | T3: AMPSTON | U3: EPE | V3: AEG | W3: TAMCO | X3: EPE | Y3: TAMCO | AA3: PILC | AB3: ABB ELEKTRIK SANAYI | AC3: PILC | AD3: ASEA LEPPER | AE3: PILC | AF3: ABB | AG3: ABB | AH3: ABB | AI3: PILC | AO3: BERKAT INSAF
A4: RMU OIL | C4: SERVICE/CLOSE | D4: MAIN/RESERVE | E4: N/A | H4: 24kV | K4: 500kVA | L4: HV BUSHING | O4: 800A | R4: FUJI | S4: GEC | T4: EPE | U4: GEC | V4: AREVA | X4: GEC | Y4: LUCY | AB4: ACEC | AD4: CHANG CHING | AF4: AEI | AG4: AEI | AH4: AEI
A5: VCB | C5: SERVICE/TRIP | D5: N/A | E5: NOT ACCESSIBLE | H5: 36kV | K5: 300kVA | L5: HV CABLE | O5: 400A | R5: GEC | S5: HITACHI | T5: FUJI | U5: HITACHI | V5: EPE | X5: ITEM | Y5: SSE | AB5: AM SGB | AD5: ELIN | AF5: ALAF CEKAL | AG5: ALAF CEKAL | AH5: ALAF CEKAL
A6: GIS | C6: TEST/TRIP | E6: BUSBAR | K6: 100kVA | L6: HV CABLE SPLIT | O6: N/A | R6: ITEM | S6: HI-VAC | T6: GEC | U6: TAMCO | V6: ITEM | X6: SIEMENS | Y6: SCHNEIDER | AB6: BHARAT | AD6: EMO-OHRID | AF6: ALGEBRA | AG6: ALGEBRA | AH6: ALGEBRA
A7: ACB | C7: RACK OUT | K7: N/A | L7: LV BUSHING | R7: MITSUBISHI | S7: TAMCO | T7: ITEM | U7: S&S AMPSTON | V7: RANHILL | X7: TAMCO | Y7: FALCON BETA | AB7: CRAIOVA | AD7: EWT | AF7: ALTENA | AG7: ALTENA | AH7: ALTENA
A8: PAT | K8: NOT ACCESSIBLE | L8: LV CABLE | R8: S&S AMPSTON | S8: TOSHIBA | T8: MEIDEN | U8: S&S POWER | V8: SIEMENS | X8: TOPRANK | Y8: TOPRANK | AB8: CRAIOVA ROMANIA | AD8: IEO TRANSFORMATOREN BREDA | AF8: AMPSTON | AG8: AMPSTON | AH8: AMPSTON
R9: S&S POWER | T9: MITSUBISHI | U9: S&S TOPRANK | V9: TAMCO | X9: TOSHIBA | Y9: EPE | AB9: ELECTRA | AD9: KIRLOSKAR | AF9: ANZECO POWER | AG9: ANZECO POWER | AH9: ANZECO POWER
R10: S&S TOPRANK | T10: RANHILL | V10: TOSHIBA | X10: TSG | Y10: ORMAZABAL | AB10: ELECTRO PUTERE | AD10: LKH | AF10: BONAR LONG | AG10: BONAR LONG | AH10: BONAR LONG
R11: SIEMENS | T11: S&S AMPSTON | V11: TSG | Y11: F&G | AB11: FUJI ELECTRIC | AD11: MINEL-TRAFO | AF11: E.A.M | AG11: E.A.M | AH11: E.A.M
R12: TAMCO | T12: S&S POWER | Y12: MERLIN GERIN | AB12: HEFEI | AD12: MITSUBISHI | AF12: EPE | AG12: EPE | AH12: EPE
R13: TOPRANK | T13: S&S TOPRANK | Y13: ABB | AB13: HERMANN MATERN | AD13: MTM | AF13: GEC | AG13: GEC | AH13: GEC
R14: TOSHIBA | T14: SIEMENS | Y14: INFRAKOMAS | AB14: HYUNDAI | AD14: NACC | AF14: INDKOM | AG14: INDKOM | AH14: INDKOM
T15: TAMCO | AB15: LEEEC | AD15: NEW KOREA | AF15: ITEM | AG15: ITEM | AH15: ITEM
T16: TOPRANK | AB16: LIAOYANG | AD16: PAUWEL TRAFO | AF16: JEAN MULLER | AG16: JEAN MULLER | AH16: JEAN MULLER
T17: TOSHIBA | AB17: MITSUBISHI | AD17: SCHNEIDER | AF17: MTM | AG17: MTM | AH17: MTM
T18: TSG | AB18: MTM | AD18: SGB | AF18: POLYPHASE | AG18: POLYPHASE | AH18: POLYPHASE
T19: VEI | AB19: NANCHANG | AD19: T.M.C.-S.A. | AF19: PRONUTEC | AG19: PRONUTEC | AH19: PRONUTEC
AB20: RADE KONCAR | AD20: TOSHIBA | AF20: PSB | AG20: PSB | AH20: PSB
AB21: SAVIGLIANO | AD21: WODEN | AF21: SCHNEIDER | AG21: SCHNEIDER | AH21: SCHNEIDER
AB22: SHENYANG | AF22: SSE | AG22: SSE | AH22: SSE
AB23: SHIHLIN | AF23: TAMCO | AG23: TAMCO | AH23: TAMCO
AB24: TAKAOKA | AF24: TAMCO CUTLER HAMMER | AG24: TAMCO CUTLER HAMMER | AH24: TAMCO CUTLER HAMMER
AB25: TUR INDIA | AF25: TAN & LOW | AG25: TAN & LOW | AH25: TAN & LOW
AB26: WILSON | AF26: TEKNIK | AG26: TEKNIK | AH26: TEKNIK
AB27: XI'AN | AF27: TENAGA | AG27: TENAGA | AH27: TENAGA
AF28: TOPRANK | AG28: TOPRANK | AH28: TOPRANK
AF29: TOSHIBA | AG29: TOSHIBA | AH29: TOSHIBA
AF30: WELL PRESTIGE | AG30: WELL PRESTIGE | AH30: WELL PRESTIGE
AF31: WOODEN | AG31: WOODEN | AH31: WOODEN
